Workbook

Sheet DIN V 18599-10
A1: Bezeichnung | B1: Nr. | C1: Wärmequelle Personen [W/p] | D1: Arbeitshilfen tief [W/m²] | E1: Arbeitshilfen mittel [W/m²] | F1: Arbeitshilfen hoch [W/m²] | G1: Nutzungszeit Start | H1: Nutzungszeit Ende
A2: Einzelbüro | B2: 1 | C2: 70 | D2: 2.8 | E2: 7.1 | F2: 15 | G2: 7 | H2: 18 | I2: 0.114
A3: Gruppenbüro (2 bis 6 Arbeitsplätze) | B3: 2 | C3: 70 | D3: 2.8 | E3: 7.1 | F3: 15 | G3: 7 | H3: 18 | I3: 0.085
A4: Großraumbüro (ab 7 Arbeitsplätze) | B4: 3 | C4: 70 | D4: 4.2 | E4: 10 | F4: 18.8 | G4: 7 | H4: 18 | I4: 0.019
A5: Besprechung/Sitzungszimmer/Seminar | B5: 4 | C5: 70 | D5: 1 | E5: 2 | F5: 3 | G5: 7 | H5: 18 | I5: 0.095
A6: Schalterhalle | B6: 5 | C6: 70 | D6: 1.5 | E6: 4 | F6: 9.5 | G6: 7 | H6: 18
A7: Einzelhandel/Kaufhaus | B7: 6 | C7: 70 | D7: 1 | E7: 2 | F7: 3 | G7: 8 | H7: 20
A8: Einzelhandel/Kaufhaus (Lebensmittelabteilung mit Kühlprodukten) | B8: 7 | C8: 70 | D8: -12 | E8: -10 | F8: -8 | G8: 8 | H8: 20
A9: Klassenzimmer (Schule), Gruppenraum (Kindergarten) | B9: 8 | C9: 60 | D9: 2 | E9: 4 | F9: 6 | G9: 8 | H9: 15
A10: Hörsaal, Auditorium | B10: 9 | C10: 70 | D10: 2 | E10: 4 | F10: 6 | G10: 8 | H10: 18 | I10: 0.036
A11: Bettenzimmer (Zweibettzimmer im Krankenhaus, Pflegeheim) | B11: 10 | C11: 70 | D11: 2 | E11: 4 | F11: 6 | G11: 0 | H11: 24
A12: Hotelzimmer (Doppelzimmer) | B12: 11 | C12: 70 | D12: 2 | E12: 4 | F12: 6 | G12: 21 | H12: 8
A13: Kantine (Kantine) | B13: 12 | C13: 70 | D13: 1 | E13: 2 | F13: 3 | G13: 8 | H13: 15
A14: Kantine (Restaurant) | B14: 13 | C14: 70 | D14: 1 | E14: 2 | F14: 3 | G14: 10 | H14: 24
A15: Küche in Nichtwohngebäuden | B15: 14 | C15: 80 | D15: 200 | E15: 300 | F15: 400 | G15: 10 | H15: 23
A16: Küche (Vorbereitung, Lager) | B16: 15 | C16: 80 | D16: 20 | E16: 30 | F16: 40 | G16: 10 | H16: 23
A17: WC und Sanitärräume in Nichtwohngebäuden | B17: 16 | C17: 70 | D17: 0 | E17: 0 | F17: 0 | G17: 7 | H17: 18 | I17: 0.026
A18: Sonstige Aufenthaltsräume (Pausenraum, Wartezimmer) | B18: 17 | C18: 70 | D18: 1 | E18: 2 | F18: 3 | G18: 7 | H18: 18 | I18: 0.048
A19: Sonstige Aufenthaltsräume (Garderobe, Teeküche, Lager, Archiv, Flur) | B19: 18 | C19: 70 | D19: 0 | E19: 0 | F19: 0 | G19: 7 | H19: 18 | I19: 0.017
A20: Verkehrsfläche (Flur) | B20: 19 | C20: 70 | D20: 0 | E20: 0 | F20: 0 | G20: 7 | H20: 18 | I20: 0.249
A21: Lager (Technik, Archiv) | B21: 20 | C21: 70 | D21: 0 | E21: 0 | F21: 0 | G21: 7 | H21: 18 | I21: 0.165
A22: Rechenzentrum | B22: 21 | C22: 70 | D22: 50 | E22: 150 | F22: 500 | G22: 0 | H22: 24
A23: Gewerbliche und industrielle Hallen (schwere Arbeit, stehende Tätigkeit) | B23: 22.1 | C23: 120 | D23: 25 | E23: 35 | F23: 45 | G23: 7 | H23: 16
A24: Gewerbliche und industrielle Hallen (mittelschwere Arbeit, überw. stehende Tätigkeit) | B24: 22.2 | C24: 100 | D24: 25 | E24: 35 | F24: 45 | G24: 7 | H24: 16
A25: Gewerbliche und industrielle Hallen (leichte Arbeit, überw. sitzende Tätigkeit) | B25: 22.3 | C25: 80 | D25: 25 | E25: 35 | F25: 45 | G25: 7 | H25: 16 | I25: 0.027
A26: Zuschauerbereich (Theater, Veranstaltungsbauten) | B26: 23 | C26: 70 | D26: 0 | E26: 0 | F26: 0 | G26: 19 | H26: 23
A27: Theater (Foyer) | B27: 24 | C27: 70 | D27: 0 | E27: 0 | F27: 0 | G27: 19 | H27: 23
A28: Bühne (Theater, Veranstaltungsbauten) | B28: 25 | C28: 70 | D28: 0 | E28: 0 | F28: 0 | G28: 13 | H28: 23
A29: Messe/Kongress | B29: 26 | C29: 70 | D29: 1 | E29: 2 | F29: 3 | G29: 13 | H29: 18
A30: Ausstellungsräume, Museum | B30: 27 | C30: 70 | D30: 0 | E30: 0 | F30: 0 | G30: 10 | H30: 18
A31: Bibliothek - Lesesaal | B31: 28 | C31: 70 | D31: 0 | E31: 0 | F31: 0 | G31: 8 | H31: 20 | I31: 0.031
A32: Bibliothek - Freihandbereich | B32: 29 | C32: 70 | D32: 0 | E32: 0 | F32: 0 | G32: 8 | H32: 20
A33: Bibliothek - Magazin und Depot | B33: 30 | C33: 70 | D33: 0 | E33: 0 | F33: 0 | G33: 8 | H33: 20
A34: Turnhalle (ohne Zuschauerbereich) | B34: 31 | C34: 125 | D34: 0 | E34: 0 | F34: 0 | G34: 8 | H34: 23
A35: Parkhaus (Büro- und Privatnutzung) | B35: 32 | C35: 70 | D35: 0 | E35: 0 | F35: 0 | G35: 7 | H35: 18
A36: Parkhaus (öffentliche Nutzung) | B36: 33 | C36: 70 | D36: 0 | E36: 0 | F36: 0 | G36: 9 | H36: 24
A37: Saunabereich | B37: 34 | C37: 70 | D37: 40 | E37: 50 | F37: 60 | G37: 10 | H37: 22
A38: Fitnessraum | B38: 35 | C38: 110 | D38: 1 | E38: 2 | F38: 3 | G38: 8 | H38: 23
A39: Labor | B39: 36 | C39: 90 | D39: 6 | E39: 18 | F39: 63 | G39: 7 | H39: 18 | I39: 0.088
A40: Fitnessraum (Untersuchungs- und Behandlungsräume) | B40: 37 | C40: 70 | D40: 4 | E40: 7 | F40: 10 | G40: 7 | H40: 18
...

Sheet SIA 2024
A1: Bezeichnung | B1: Gebäudekategorie | C1: Nr. | D1: Wärmequelle Personen [W/p] | E1: Arbeitshilfen Standard [W/m²] | F1: Arbeitshilfen Zielwert [W/m²] | G1: Arbeitshilfen Bestand [W/m²] | H1: Nutzungszeit Start | I1: Nutzungszeit Ende | J1: Außenluftvolumenstrom
A2: Wohnen MFH | B2: Wohnen | C2: 1.1 | D2: 70 | E2: 8 | F2: 4 | G2: 10 | H2: 0 | I2: 24 | J2: 1
A3: Wohnen EFH | B3: Wohnen | C3: 1.2 | D3: 70 | E3: 8 | F3: 4 | G3: 10 | H3: 0 | I3: 24 | J3: 0.6
A4: Hotelzimmer | B4: Hotel | C4: 2.1 | D4: 70 | E4: 8 | F4: 4 | G4: 10 | H4: 17 | I4: 12 | J4: 2.4
A5: Empfang, Lobby | B5: Hotel | C5: 2.2 | D5: 70 | E5: 7 | F5: 3 | G5: 15 | H5: 4 | I5: 24 | J5: 7.2
A6: Einzel-, Gruppenbüro | B6: Verwaltung | C6: 3.1 | D6: 70 | E6: 7 | F6: 3 | G6: 15 | H6: 7 | I6: 18 | J6: 2.6
A7: Großraumbüro | B7: Verwaltung | C7: 3.2 | D7: 70 | E7: 10 | F7: 4 | G7: 19 | H7: 7 | I7: 18 | J7: 3.6
A8: Sitzungszimmer | B8: Verwaltung | C8: 3.3 | D8: 70 | E8: 2 | F8: 1 | G8: 3 | H8: 9 | I8: 17 | J8: 12
A9: Schalterhalle, Empfang | B9: Verwaltung | C9: 3.4 | D9: 70 | E9: 4 | F9: 1.5 | G9: 9.5 | H9: 7 | I9: 18 | J9: 2.5
A10: Schulzimmer | B10: Schulen | C10: 4.1 | D10: 70 | E10: 4 | F10: 2 | G10: 6 | H10: 7 | I10: 18 | J10: 8.3
A11: Lehrerzimmer | B11: Schulen | C11: 4.2 | D11: 70 | E11: 4 | F11: 2 | G11: 6 | H11: 7 | I11: 18 | J11: 12
A12: Bibliothek | B12: Schulen | C12: 4.3 | D12: 70 | E12: 2 | F12: 1 | G12: 3 | H12: 7 | I12: 18 | J12: 7.2
A13: Hörsaal | B13: Schulen | C13: 4.4 | D13: 70 | E13: 4 | F13: 2 | G13: 6 | H13: 7 | I13: 18 | J13: 15
A14: Schulfachraum | B14: Schulen | C14: 4.5 | D14: 70 | E14: 4 | F14: 1.5 | G14: 9.5 | H14: 7 | I14: 18 | J14: 6
A15: Lebensmittelverkauf | B15: Verkauf | C15: 5.1 | D15: 70 | E15: -10 | F15: -8 | G15: -12 | H15: 7 | I15: 20 | J15: 3.8
A16: Fachgeschäft | B16: Verkauf | C16: 5.2 | D16: 70 | E16: 2 | F16: 1 | G16: 3 | H16: 7 | I16: 20 | J16: 3.8
A17: Verkauf Möbel, Bau, Garten | B17: Verkauf | C17: 5.3 | D17: 70 | E17: 2 | F17: 1 | G17: 3 | H17: 7 | I17: 19 | J17: 2
A18: Restaurant | B18: Restaurant | C18: 6.1 | D18: 70 | E18: 2 | F18: 1 | G18: 3 | H18: 8 | I18: 24 | J18: 18
A19: Selbstbedienungsrestaurant | B19: Restaurant | C19: 6.2 | D19: 70 | E19: 2 | F19: 1 | G19: 3 | H19: 8 | I19: 15 | J19: 18
A20: Küche zu Restaurant | B20: Restaurant | C20: 6.3 | D20: 90 | E20: 200 | F20: 150 | G20: 250 | H20: 8 | I20: 23 | J20: 20
A21: Küche zu Selbstbedienungsrestaurant | B21: Restaurant | C21: 6.4 | D21: 90 | E21: 200 | F21: 150 | G21: 250 | H21: 7 | I21: 16 | J21: 20
A22: Vorstellungsraum | B22: Versammlungslokale | C22: 7.1 | D22: 70 | E22: 2 | F22: 1 | G22: 3 | H22: 12 | I22: 24 | J22: 12
A23: Mehrzweckhalle | B23: Versammlungslokale | C23: 7.2 | D23: 70 | E23: 4 | F23: 2 | G23: 6 | H23: 7 | I23: 23 | J23: 12
A24: Ausstellungshalle | B24: Versammlungslokale | C24: 7.3 | D24: 70 | E24: 7 | F24: 3 | G24: 15 | H24: 7 | I24: 23 | J24: 12
A25: Bettenzimmer | B25: Spitäler | C25: 8.1 | D25: 70 | E25: 4 | F25: 2 | G25: 6 | H25: 0 | I25: 24 | J25: 2.4
A26: Stationszimmer | B26: Spitäler | C26: 8.2 | D26: 70 | E26: 7 | F26: 3 | G26: 15 | H26: 0 | I26: 24 | J26: 12
... A42: Garderobe, Dusche | B42: zugeordnete Nutzungen | C42: 12.8 | D42: 70 | E42: 0 | F42: 0 | G42: 0 | H42: 7 | I42: 18 | J42: 20
A43: Parkhaus | B43: zugeordnete Nutzungen | C43: 12.9 | D43: 70 | E43: 1 | F43: 0.5 | G43: 2 | H43: 7 | I43: 18 | J43: 2
A44: Wasch- und Trockenraum | B44: zugeordnete Nutzungen | C44: 12.10 | D44: 70 | E44: 20 | F44: 15 | G44: 25 | H44: 7 | I44: 18 | J44: 4
A45: Kühlraum | B45: zugeordnete Nutzungen | C45: 12.11 | D45: 70 | E45: 0 | F45: 0 | G45: 0
A46: Serverraum | B46: zugeordnete Nutzungen | C46: 12.12 | D46: 70 | E46: 100 | F46: 50 | G46: 150 | H46: 7 | I46: 18 | J46: 2

Sheet MZA
A1: ID_Enob_lfd | B1: ID_HK_UK_Enob_long | C1: Bez_HK_Enob | D1: Bez_UK_Enob | E1: ID_Enob_lfd | F1: t_start | G1: t_end | H1: t_nutz_d | I1: d_nutz_a | J1: t_Tag | K1: t_Nacht | L1: t_v_op_d | M1: d_op_a | N1: t_h_op_d | O1: E_m | P1: h_Ne | Q1: k_A | R1: C_A | S1: k | T1: F_t | U1: k_VB | V1: theta_i_h_soll | W1: theta_i_c_soll | X1: deltaTheta_i_NA | Y1: theta_i_h_min | Z1: theta_i_c_max | AA1: Feuchte | AB1: Vd_A | AC1: Vd_A_Geb | AD1: c_RLT | AE1: F_RLT | AF1: q_I_p | AG1: q_I_fac | AI1: =F1 -> t_start | AJ1: =G1 -> t_end | AK1: =H1 -> t_nutz_d | AL1: =I1 -> d_nutz_a | AM1: =J1 -> t_Tag | AN1: =K1 -> t_Nacht | AO1: =L1 -> t_v_op_d | AP1: =M1 -> d_op_a | ... BJ1: =AG1 -> q_I_fac
A2: 1 | B2: HK_UK_1-0 | C2: Büro-, Verwaltungs- oder Amtsgebäude | E2: 1 | F2: 6.7636033 | G2: 18.345491 | H2: 11.581887 | I2: 256.56318 | J2: 2622.4483 | K2: 416.13092 | L2: 13.195568 | M2: 256.56318 | N2: 13.132597 | O2: 328.0346 | P2: 0.69262897 | Q2: 0.94388636 | R2: 0.49809137 | S2: 1.3379322 | T2: 0.87771349 | U2: 1.1176933 | V2: 20.906347 | W2: 24.033088 | X2: 3.9706969 | Y2: 19.900379 | Z2: 26.033088 | AA2: 0.59532715 | AB2: 5.0131547 | AC2: 1.7366067 | AD2: 0.23036084 | AE2: 0.86095232 | AF2: 70.472123 | AG2: 7.7181618 | AI2: =IF(MID(F2,2,1)=",",_xlfn.TEXTJOIN(".",FALSE,MID(F2,1,1),MID(F2,3,LEN(F2)-2)),IF(MID(F2,3,1)=",",_xlfn.TEXTJOIN(".",FALSE,MID(F2,1,2),MID(F2,4,LEN(F2)-3)),IF(MID(F2,4,1)=",",_xlfn.TEXTJOIN(".",FALSE,MID(F2,1,3),MID(F2,5,LEN(F2)-4)),IF(MID(F2,5,1)=",",_xlfn.TEXTJOIN(".",FALSE,MID(F2,1,4),MID(F2,6,LEN(F2)-5)),F2)))) -> 6.763603261 | AJ2: =IF(MID(G2,2,1)=",",_xlfn.TEXTJOIN(".",FALSE,MID(G2,1,1),MID(G2,3,LEN(G2)-2)),IF(MID(G2,3,1)=",",_xlfn.TEXTJOIN(".",FALSE,MID(G2,1,2),MID(G2,4,LEN(G2)-3)),IF(MID(G2,4,1)=",",_xlfn.TEXTJOIN(".",FALSE,MID(G2,1,3),MID(G2,5,LEN(G2)-4)),IF(MID(G2,5,1)=",",_xlfn.TEXTJOIN(".",FALSE,MID(G2,1,4),MID(G2,6,LEN(G2)-5)),G2)))) -> 18.34549056 | AK2: =IF(MID(H2,2,1)=",",_xlfn.TEXTJOIN(".",FALSE,MID(H2,1,1),MID(H2,3,LEN(H2)-2)),IF(MID(H2,3,1)=",",_xlfn.TEXTJOIN(".",FALSE,MID(H2,1,2),MID(H2,4,LEN(H2)-3)),IF(MID(H2,4,1)=",",_xlfn.TEXTJOIN(".",FALSE,MID(H2,1,3),MID(H2,5,LEN(H2)-4)),IF(MID(H2,5,1)=",",_xlfn.TEXTJOIN(".",FALSE,MID(H2,1,4),MID(H2,6,LEN(H2)-5)),H2)))) -> 11.5818873 | AL2: =IF(MID(I2,2,1)=",",_xlfn.TEXTJOIN(".",FALSE,MID(I2,1,1),MID(I2,3,LEN(I2)-2)),IF(MID(I2,3,1)=",",_xlfn.TEXTJOIN(".",FALSE,MID(I2,1,2),MID(I2,4,LEN(I2)-3)),IF(MID(I2,4,1)=",",_xlfn.TEXTJOIN(".",FALSE,MID(I2,1,3),MID(I2,5,LEN(I2)-4)),IF(MID(I2,5,1)=",",_xlfn.TEXTJOIN(".",FALSE,MID(I2,1,4),MID(I2,6,LEN(I2)-5)),I2)))) -> 256.563179 | AM2: =IF(MID(J2,2,1)=",",_xlfn.TEXTJOIN(".",FALSE,MID(J2,1,1),MID(J2,3,LEN(J2)-2)),IF(MID(J2,3,1)=",",_xlfn.TEXTJOIN(".",FALSE,MID(J2,1,2),MID(J2,4,LEN(J2)-3)),IF(MID(J2,4,1)=",",_xlfn.TEXTJOIN(".",FALSE,MID(J2,1,3),MID(J2,5,LEN(J2)-4)),IF(MID(J2,5,1)=",",_xlfn.TEXTJOIN(".",FALSE,MID(J2,1,4),MID(J2,6,LEN(J2)-5)),J2)))) -> 2622.448342 | AN2: =IF(MID(K2,2,1)=",",_xlfn.TEXTJOIN(".",FALSE,MID(K2,1,1),MID(K2,3,LEN(K2)-2)),IF(MID(K2,3,1)=",",_xlfn.TEXTJOIN(".",FALSE,MID(K2,1,2),MID(K2,4,LEN(K2)-3)),IF(MID(K2,4,1)=",",_xlfn.TEXTJOIN(".",FALSE,MID(K2,1,3),MID(K2,5,LEN(K2)-4)),IF(MID(K2,5,1)=",",_xlfn.TEXTJOIN(".",FALSE,MID(K2,1,4),MID(K2,6,LEN(K2)-5)),K2)))) -> 416.1309153 | AO2: =IF(MID(L2,2,1)=",",_xlfn.TEXTJOIN(".",FALSE,MID(L2,1,1),MID(L2,3,LEN(L2)-2)),IF(MID(L2,3,1)=",",_xlfn.TEXTJOIN(".",FALSE,MID(L2,1,2),MID(L2,4,LEN(L2)-3)),IF(MID(L2,4,1)=",",_xlfn.TEXTJOIN(".",FALSE,MID(L2,1,3),MID(L2,5,LEN(L2)-4)),IF(MID(L2,5,1)=",",_xlfn.TEXTJOIN(".",FALSE,MID(L2,1,4),MID(L2,6,LEN(L2)-5)),L2)))) -> 13.19556784 | AP2: =IF(MID(M2,2,1)=",",_xlfn.TEXTJOIN(".",FALSE,MID(M2,1,1),MID(M2,3,LEN(M2)-2)),IF(MID(M2,3,1)=",",_xlfn.TEXTJOIN(".",FALSE,MID(M2,1,2),MID(M2,4,LEN(M2)-3)),IF(MID(M2,4,1)=",",_xlfn.TEXTJOIN(".",FALSE,MID(M2,1,3),MID(M2,5,LEN(M2)-4)),IF(MID(M2,5,1)=",",_xlfn.TEXTJOIN(".",FALSE,MID(M2,1,4),MID(M2,6,LEN(M2)-5)),M2)))) -> 256.563179 | ... BJ2: =IF(MID(AG2,2,1)=",",_xlfn.TEXTJOIN(".",FALSE,MID(AG2,1,1),MID(AG2,3,LEN(AG2)-2)),IF(MID(AG2,3,1)=",",_xlfn.TEXTJOIN(".",FALSE,MID(AG2,1,2),MID(AG2,4,LEN(AG2)-3)),IF(MID(AG2,4,1)=",",_xlfn.TEXTJOIN(".",FALSE,MID(AG2,1,3),MID(AG2,5,LEN(AG2)-4)),IF(MID(AG2,5,1)=",",_xlfn.TEXTJOIN(".",FALSE,MID(AG2,1,4),MID(AG2,6,LEN(AG2)-5)),AG2)))) -> 7.718161762
A3: 2 | B3: HK_UK_1-1 | C3: Büro-, Verwaltungs- oder Amtsgebäude | D3: Parlaments- oder Gerichtsgebäude | E3: 2 | F3: 6.9260843 | G3: 18.092084 | H3: 11.166 | I3: 251.97212 | J3: 2560.5103 | K3: 272.29654 | L3: 13.066148 | M3: 251.97212 | N3: 13.066148 | O3: 285.18519 | P3: 0.63623624 | Q3: 0.9472973 | R3: 0.62497506 | S3: 1.0946446 | T3: 0.89057473 | U3: 1.1775919 | V3: 21 | W3: 24 | X3: 3.995996 | Y3: 20 | Z3: 26 | AA3: 0.46646647 | AB3: 4.0341341 | AC3: 1.4284284 | AD3: 0.19842756 | AE3: 0.85069567 | AF3: 70.035917 | AG3: 4.6189165 | AI3: =IF(MID(F3,2,1)=",",_xlfn.TEXTJOIN(".",FALSE,MID(F3,1,1),MID(F3,3,LEN(F3)-2)),IF(MID(F3,3,1)=",",_xlfn.TEXTJOIN(".",FALSE,MID(F3,1,2),MID(F3,4,LEN(F3)-3)),IF(MID(F3,4,1)=",",_xlfn.TEXTJOIN(".",FALSE,MID(F3,1,3),MID(F3,5,LEN(F3)-4)),IF(MID(F3,5,1)=",",_xlfn.TEXTJOIN(".",FALSE,MID(F3,1,4),MID(F3,6,LEN(F3)-5)),F3)))) -> 6.926084266 | AJ3: =IF(MID(G3,2,1)=",",_xlfn.TEXTJOIN(".",FALSE,MID(G3,1,1),MID(G3,3,LEN(G3)-2)),IF(MID(G3,3,1)=",",_xlfn.TEXTJOIN(".",FALSE,MID(G3,1,2),MID(G3,4,LEN(G3)-3)),IF(MID(G3,4,1)=",",_xlfn.TEXTJOIN(".",FALSE,MID(G3,1,3),MID(G3,5,LEN(G3)-4)),IF(MID(G3,5,1)=",",_xlfn.TEXTJOIN(".",FALSE,MID(G3,1,4),MID(G3,6,LEN(G3)-5)),G3)))) -> 18.0920844 | AK3: =IF(MID(H3,2,1)=",",_xlfn.TEXTJOIN(".",FALSE,MID(H3,1,1),MID(H3,3,LEN(H3)-2)),IF(MID(H3,3,1)=",",_xlfn.TEXTJOIN(".",FALSE,MID(H3,1,2),MID(H3,4,LEN(H3)-3)),IF(MID(H3,4,1)=",",_xlfn.TEXTJOIN(".",FALSE,MID(H3,1,3),MID(H3,5,LEN(H3)-4)),IF(MID(H3,5,1)=",",_xlfn.TEXTJOIN(".",FALSE,MID(H3,1,4),MID(H3,6,LEN(H3)-5)),H3)))) -> 11.16600013 | AL3: =IF(MID(I3,2,1)=",",_xlfn.TEXTJOIN(".",FALSE,MID(I3,1,1),MID(I3,3,LEN(I3)-2)),IF(MID(I3,3,1)=",",_xlfn.TEXTJOIN(".",FALSE,MID(I3,1,2),MID(I3,4,LEN(I3)-3)),IF(MID(I3,4,1)=",",_xlfn.TEXTJOIN(".",FALSE,MID(I3,1,3),MID(I3,5,LEN(I3)-4)),IF(MID(I3,5,1)=",",_xlfn.TEXTJOIN(".",FALSE,MID(I3,1,4),MID(I3,6,LEN(I3)-5)),I3)))) -> 251.9721174 | AM3: =IF(MID(J3,2,1)=",",_xlfn.TEXTJOIN(".",FALSE,MID(J3,1,1),MID(J3,3,LEN(J3)-2)),IF(MID(J3,3,1)=",",_xlfn.TEXTJOIN(".",FALSE,MID(J3,1,2),MID(J3,4,LEN(J3)-3)),IF(MID(J3,4,1)=",",_xlfn.TEXTJOIN(".",FALSE,MID(J3,1,3),MID(J3,5,LEN(J3)-4)),IF(MID(J3,5,1)=",",_xlfn.TEXTJOIN(".",FALSE,MID(J3,1,4),MID(J3,6,LEN(J3)-5)),J3)))) -> 2560.51029 | AN3: =IF(MID(K3,2,1)=",",_xlfn.TEXTJOIN(".",FALSE,MID(K3,1,1),MID(K3,3,LEN(K3)-2)),IF(MID(K3,3,1)=",",_xlfn.TEXTJOIN(".",FALSE,MID(K3,1,2),MID(K3,4,LEN(K3)-3)),IF(MID(K3,4,1)=",",_xlfn.TEXTJOIN(".",FALSE,MID(K3,1,3),MID(K3,5,LEN(K3)-4)),IF(MID(K3,5,1)=",",_xlfn.TEXTJOIN(".",FALSE,MID(K3,1,4),MID(K3,6,LEN(K3)-5)),K3)))) -> 272.296536 | AO3: =IF(MID(L3,2,1)=",",_xlfn.TEXTJOIN(".",FALSE,MID(L3,1,1),MID(L3,3,LEN(L3)-2)),IF(MID(L3,3,1)=",",_xlfn.TEXTJOIN(".",FALSE,MID(L3,1,2),MID(L3,4,LEN(L3)-3)),IF(MID(L3,4,1)=",",_xlfn.TEXTJOIN(".",FALSE,MID(L3,1,3),MID(L3,5,LEN(L3)-4)),IF(MID(L3,5,1)=",",_xlfn.TEXTJOIN(".",FALSE,MID(L3,1,4),MID(L3,6,LEN(L3)-5)),L3)))) -> 13.06614786 | AP3: =IF(MID(M3,2,1)=",",_xlfn.TEXTJOIN(".",FALSE,MID(M3,1,1),MID(M3,3,LEN(M3)-2)),IF(MID(M3,3,1)=",",_xlfn.TEXTJOIN(".",FALSE,MID(M3,1,2),MID(M3,4,LEN(M3)-3)),IF(MID(M3,4,1)=",",_xlfn.TEXTJOIN(".",FALSE,MID(M3,1,3),MID(M3,5,LEN(M3)-4)),IF(MID(M3,5,1)=",",_xlfn.TEXTJOIN(".",FALSE,MID(M3,1,4),MID(M3,6,LEN(M3)-5)),M3)))) -> 251.9721174 | ... BJ3: =IF(MID(AG3,2,1)=",",_xlfn.TEXTJOIN(".",FALSE,MID(AG3,1,1),MID(AG3,3,LEN(AG3)-2)),IF(MID(AG3,3,1)=",",_xlfn.TEXTJOIN(".",FALSE,MID(AG3,1,2),MID(AG3,4,LEN(AG3)-3)),IF(MID(AG3,4,1)=",",_xlfn.TEXTJOIN(".",FALSE,MID(AG3,1,3),MID(AG3,5,LEN(AG3)-4)),IF(MID(AG3,5,1)=",",_xlfn.TEXTJOIN(".",FALSE,MID(AG3,1,4),MID(AG3,6,LEN(AG3)-5)),AG3)))) -> 4.618916492
A4: 3 | B4: HK_UK_1-2 | C4: Büro-, Verwaltungs- oder Amtsgebäude | D4: Öffentliches Verwaltungs- oder Ämtergebäude, Rathaus | E4: 3 | F4: 7.0342809 | G4: 18.225194 | H4: 11.190913 | I4: 253.66283 | J4: 2570.604 | K4: 286.46176 | L4: 13.105393 | M4: 253.72171 | N4: 13.104309 | O4: 322.05155 | P4: 0.68321987 | Q4: 0.93675244 | R4: 0.54056171 | S4: 1.1394299 | T4: 0.87039775 | U4: 1.136235 | V4: 20.986451 | W4: 24.008128 | X4: 4 | Y4: 19.986926 | Z4: 26.008128 | AA4: 0.57918781 | AB4: 4.5429275 | AC4: 1.6183658 | AD4: 0.21866548 | AE4: 0.8279079 | AF4: 70.152019 | AG4: 5.706488 | AI4: =IF(MID(F4,2,1)=",",_xlfn.TEXTJOIN(".",FALSE,MID(F4,1,1),MID(F4,3,LEN(F4)-2)),IF(MID(F4,3,1)=",",_xlfn.TEXTJOIN(".",FALSE,MID(F4,1,2),MID(F4,4,LEN(F4)-3)),IF(MID(F4,4,1)=",",_xlfn.TEXTJOIN(".",FALSE,MID(F4,1,3),MID(F4,5,LEN(F4)-4)),IF(MID(F4,5,1)=",",_xlfn.TEXTJOIN(".",FALSE,MID(F4,1,4),MID(F4,6,LEN(F4)-5)),F4)))) -> 7.034280901 | AJ4: =IF(MID(G4,2,1)=",",_xlfn.TEXTJOIN(".",FALSE,MID(G4,1,1),MID(G4,3,LEN(G4)-2)),IF(MID(G4,3,1)=",",_xlfn.TEXTJOIN(".",FALSE,MID(G4,1,2),MID(G4,4,LEN(G4)-3)),IF(MID(G4,4,1)=",",_xlfn.TEXTJOIN(".",FALSE,MID(G4,1,3),MID(G4,5,LEN(G4)-4)),IF(MID(G4,5,1)=",",_xlfn.TEXTJOIN(".",FALSE,MID(G4,1,4),MID(G4,6,LEN(G4)-5)),G4)))) -> 18.22519399 | AK4: =IF(MID(H4,2,1)=",",_xlfn.TEXTJOIN(".",FALSE,MID(H4,1,1),MID(H4,3,LEN(H4)-2)),IF(MID(H4,3,1)=",",_xlfn.TEXTJOIN(".",FALSE,MID(H4,1,2),MID(H4,4,LEN(H4)-3)),IF(MID(H4,4,1)=",",_xlfn.TEXTJOIN(".",FALSE,MID(H4,1,3),MID(H4,5,LEN(H4)-4)),IF(MID(H4,5,1)=",",_xlfn.TEXTJOIN(".",FALSE,MID(H4,1,4),MID(H4,6,LEN(H4)-5)),H4)))) -> 11.19091309 | AL4: =IF(MID(I4,2,1)=",",_xlfn.TEXTJOIN(".",FALSE,MID(I4,1,1),MID(I4,3,LEN(I4)-2)),IF(MID(I4,3,1)=",",_xlfn.TEXTJOIN(".",FALSE,MID(I4,1,2),MID(I4,4,LEN(I4)-3)),IF(MID(I4,4,1)=",",_xlfn.TEXTJOIN(".",FALSE,MID(I4,1,3),MID(I4,5,LEN(I4)-4)),IF(MID(I4,5,1)=",",_xlfn.TEXTJOIN(".",FALSE,MID(I4,1,4),MID(I4,6,LEN(I4)-5)),I4)))) -> 253.6628335 | AM4: =IF(MID(J4,2,1)=",",_xlfn.TEXTJOIN(".",FALSE,MID(J4,1,1),MID(J4,3,LEN(J4)-2)),IF(MID(J4,3,1)=",",_xlfn.TEXTJOIN(".",FALSE,MID(J4,1,2),MID(J4,4,LEN(J4)-3)),IF(MID(J4,4,1)=",",_xlfn.TEXTJOIN(".",FALSE,MID(J4,1,3),MID(J4,5,LEN(J4)-4)),IF(MID(J4,5,1)=",",_xlfn.TEXTJOIN(".",FALSE,MID(J4,1,4),MID(J4,6,LEN(J4)-5)),J4)))) -> 2570.604022 | AN4: =IF(MID(K4,2,1)=",",_xlfn.TEXTJOIN(".",FALSE,MID(K4,1,1),MID(K4,3,LEN(K4)-2)),IF(MID(K4,3,1)=",",_xlfn.TEXTJOIN(".",FALSE,MID(K4,1,2),MID(K4,4,LEN(K4)-3)),IF(MID(K4,4,1)=",",_xlfn.TEXTJOIN(".",FALSE,MID(K4,1,3),MID(K4,5,LEN(K4)-4)),IF(MID(K4,5,1)=",",_xlfn.TEXTJOIN(".",FALSE,MID(K4,1,4),MID(K4,6,LEN(K4)-5)),K4)))) -> 286.4617644 | AO4: =IF(MID(L4,2,1)=",",_xlfn.TEXTJOIN(".",FALSE,MID(L4,1,1),MID(L4,3,LEN(L4)-2)),IF(MID(L4,3,1)=",",_xlfn.TEXTJOIN(".",FALSE,MID(L4,1,2),MID(L4,4,LEN(L4)-3)),IF(MID(L4,4,1)=",",_xlfn.TEXTJOIN(".",FALSE,MID(L4,1,3),MID(L4,5,LEN(L4)-4)),IF(MID(L4,5,1)=",",_xlfn.TEXTJOIN(".",FALSE,MID(L4,1,4),MID(L4,6,LEN(L4)-5)),L4)))) -> 13.10539306 | AP4: =IF(MID(M4,2,1)=",",_xlfn.TEXTJOIN(".",FALSE,MID(M4,1,1),MID(M4,3,LEN(M4)-2)),IF(MID(M4,3,1)=",",_xlfn.TEXTJOIN(".",FALSE,MID(M4,1,2),MID(M4,4,LEN(M4)-3)),IF(MID(M4,4,1)=",",_xlfn.TEXTJOIN(".",FALSE,MID(M4,1,3),MID(M4,5,LEN(M4)-4)),IF(MID(M4,5,1)=",",_xlfn.TEXTJOIN(".",FALSE,MID(M4,1,4),MID(M4,6,LEN(M4)-5)),M4)))) -> 253.7217095 | ... BJ4: =IF(MID(AG4,2,1)=",",_xlfn.TEXTJOIN(".",FALSE,MID(AG4,1,1),MID(AG4,3,LEN(AG4)-2)),IF(MID(AG4,3,1)=",",_xlfn.TEXTJOIN(".",FALSE,MID(AG4,1,2),MID(AG4,4,LEN(AG4)-3)),IF(MID(AG4,4,1)=",",_xlfn.TEXTJOIN(".",FALSE,MID(AG4,1,3),MID(AG4,5,LEN(AG4)-4)),IF(MID(AG4,5,1)=",",_xlfn.TEXTJOIN(".",FALSE,MID(AG4,1,4),MID(AG4,6,LEN(AG4)-5)),AG4)))) -> 5.70648799
A5: 4 | B5: HK_UK_1-3 | C5: Büro-, Verwaltungs- oder Amtsgebäude | D5: Bürogebäude | E5: 4 | F5: 6.5090057 | G5: 18.563672 | H5: 12.054667 | I5: 261.80852 | J5: 2682.8722 | K5: 588.18498 | L5: 13.447432 | M5: 261.86131 | N5: 13.32128 | O5: 301.63545 | P5: 0.69158249 | Q5: 0.94582127 | R5: 0.51195064 | S5: 1.347681 | T5: 0.87624442 | U5: 1.1549883 | V5: 20.821175 | W5: 24.068869 | X5: 3.9244843 | Y5: 19.818476 | Z5: 26.068869 | AA5: 0.55304685 | AB5: 5.0473201 | AC5: 1.6450559 | AD5: 0.23037561 | AE5: 0.87816494 | AF5: 70.835352 | AG5: 8.1965336 | AI5: =IF(MID(F5,2,1)=",",_xlfn.TEXTJOIN(".",FALSE,MID(F5,1,1),MID(F5,3,LEN(F5)-2)),IF(MID(F5,3,1)=",",_xlfn.TEXTJOIN(".",FALSE,MID(F5,1,2),MID(F5,4,LEN(F5)-3)),IF(MID(F5,4,1)=",",_xlfn.TEXTJOIN(".",FALSE,MID(F5,1,3),MID(F5,5,LEN(F5)-4)),IF(MID(F5,5,1)=",",_xlfn.TEXTJOIN(".",FALSE,MID(F5,1,4),MID(F5,6,LEN(F5)-5)),F5)))) -> 6.509005669 | AJ5: =IF(MID(G5,2,1)=",",_xlfn.TEXTJOIN(".",FALSE,MID(G5,1,1),MID(G5,3,LEN(G5)-2)),IF(MID(G5,3,1)=",",_xlfn.TEXTJOIN(".",FALSE,MID(G5,1,2),MID(G5,4,LEN(G5)-3)),IF(MID(G5,4,1)=",",_xlfn.TEXTJOIN(".",FALSE,MID(G5,1,3),MID(G5,5,LEN(G5)-4)),IF(MID(G5,5,1)=",",_xlfn.TEXTJOIN(".",FALSE,MID(G5,1,4),MID(G5,6,LEN(G5)-5)),G5)))) -> 18.56367248 | AK5: =IF(MID(H5,2,1)=",",_xlfn.TEXTJOIN(".",FALSE,MID(H5,1,1),MID(H5,3,LEN(H5)-2)),IF(MID(H5,3,1)=",",_xlfn.TEXTJOIN(".",FALSE,MID(H5,1,2),MID(H5,4,LEN(H5)-3)),IF(MID(H5,4,1)=",",_xlfn.TEXTJOIN(".",FALSE,MID(H5,1,3),MID(H5,5,LEN(H5)-4)),IF(MID(H5,5,1)=",",_xlfn.TEXTJOIN(".",FALSE,MID(H5,1,4),MID(H5,6,LEN(H5)-5)),H5)))) -> 12.05466682 | AL5: =IF(MID(I5,2,1)=",",_xlfn.TEXTJOIN(".",FALSE,MID(I5,1,1),MID(I5,3,LEN(I5)-2)),IF(MID(I5,3,1)=",",_xlfn.TEXTJOIN(".",FALSE,MID(I5,1,2),MID(I5,4,LEN(I5)-3)),IF(MID(I5,4,1)=",",_xlfn.TEXTJOIN(".",FALSE,MID(I5,1,3),MID(I5,5,LEN(I5)-4)),IF(MID(I5,5,1)=",",_xlfn.TEXTJOIN(".",FALSE,MID(I5,1,4),MID(I5,6,LEN(I5)-5)),I5)))) -> 261.808516 | AM5: =IF(MID(J5,2,1)=",",_xlfn.TEXTJOIN(".",FALSE,MID(J5,1,1),MID(J5,3,LEN(J5)-2)),IF(MID(J5,3,1)=",",_xlfn.TEXTJOIN(".",FALSE,MID(J5,1,2),MID(J5,4,LEN(J5)-3)),IF(MID(J5,4,1)=",",_xlfn.TEXTJOIN(".",FALSE,MID(J5,1,3),MID(J5,5,LEN(J5)-4)),IF(MID(J5,5,1)=",",_xlfn.TEXTJOIN(".",FALSE,MID(J5,1,4),MID(J5,6,LEN(J5)-5)),J5)))) -> 2682.872187 | AN5: =IF(MID(K5,2,1)=",",_xlfn.TEXTJOIN(".",FALSE,MID(K5,1,1),MID(K5,3,LEN(K5)-2)),IF(MID(K5,3,1)=",",_xlfn.TEXTJOIN(".",FALSE,MID(K5,1,2),MID(K5,4,LEN(K5)-3)),IF(MID(K5,4,1)=",",_xlfn.TEXTJOIN(".",FALSE,MID(K5,1,3),MID(K5,5,LEN(K5)-4)),IF(MID(K5,5,1)=",",_xlfn.TEXTJOIN(".",FALSE,MID(K5,1,4),MID(K5,6,LEN(K5)-5)),K5)))) -> 588.1849822 | AO5: =IF(MID(L5,2,1)=",",_xlfn.TEXTJOIN(".",FALSE,MID(L5,1,1),MID(L5,3,LEN(L5)-2)),IF(MID(L5,3,1)=",",_xlfn.TEXTJOIN(".",FALSE,MID(L5,1,2),MID(L5,4,LEN(L5)-3)),IF(MID(L5,4,1)=",",_xlfn.TEXTJOIN(".",FALSE,MID(L5,1,3),MID(L5,5,LEN(L5)-4)),IF(MID(L5,5,1)=",",_xlfn.TEXTJOIN(".",FALSE,MID(L5,1,4),MID(L5,6,LEN(L5)-5)),L5)))) -> 13.44743243 | AP5: =IF(MID(M5,2,1)=",",_xlfn.TEXTJOIN(".",FALSE,MID(M5,1,1),MID(M5,3,LEN(M5)-2)),IF(MID(M5,3,1)=",",_xlfn.TEXTJOIN(".",FALSE,MID(M5,1,2),MID(M5,4,LEN(M5)-3)),IF(MID(M5,4,1)=",",_xlfn.TEXTJOIN(".",FALSE,MID(M5,1,3),MID(M5,5,LEN(M5)-4)),IF(MID(M5,5,1)=",",_xlfn.TEXTJOIN(".",FALSE,MID(M5,1,4),MID(M5,6,LEN(M5)-5)),M5)))) -> 261.8613074 | ... BJ5: =IF(MID(AG5,2,1)=",",_xlfn.TEXTJOIN(".",FALSE,MID(AG5,1,1),MID(AG5,3,LEN(AG5)-2)),IF(MID(AG5,3,1)=",",_xlfn.TEXTJOIN(".",FALSE,MID(AG5,1,2),MID(AG5,4,LEN(AG5)-3)),IF(MID(AG5,4,1)=",",_xlfn.TEXTJOIN(".",FALSE,MID(AG5,1,3),MID(AG5,5,LEN(AG5)-4)),IF(MID(AG5,5,1)=",",_xlfn.TEXTJOIN(".",FALSE,MID(AG5,1,4),MID(AG5,6,LEN(AG5)-5)),AG5)))) -> 8.196533564
A6: 5 | B6: HK_UK_1-4 | C6: Büro-, Verwaltungs- oder Amtsgebäude | D6: Rundfunk- oder Fernsehanstalt | E6: 5 | F6: 6.5090057 | G6: 18.563672 | H6: 12.054667 | I6: 261.80852 | J6: 2682.8722 | K6: 588.18498 | L6: 13.447432 | M6: 261.86131 | N6: 13.32128 | O6: 301.63545 | P6: 0.69158249 | Q6: 0.94582127 | R6: 0.51195064 | S6: 1.347681 | T6: 0.87624442 | U6: 1.1549883 | V6: 20.821175 | W6: 24.068869 | X6: 3.9244843 | Y6: 19.818476 | Z6: 26.068869 | AA6: 0.55304685 | AB6: 5.0473201 | AC6: 1.6450559 | AD6: 0.23037561 | AE6: 0.87816494 | AF6: 70.835352 | AG6: 8.1965336 | AI6: =IF(MID(F6,2,1)=",",_xlfn.TEXTJOIN(".",FALSE,MID(F6,1,1),MID(F6,3,LEN(F6)-2)),IF(MID(F6,3,1)=",",_xlfn.TEXTJOIN(".",FALSE,MID(F6,1,2),MID(F6,4,LEN(F6)-3)),IF(MID(F6,4,1)=",",_xlfn.TEXTJOIN(".",FALSE,MID(F6,1,3),MID(F6,5,LEN(F6)-4)),IF(MID(F6,5,1)=",",_xlfn.TEXTJOIN(".",FALSE,MID(F6,1,4),MID(F6,6,LEN(F6)-5)),F6)))) -> 6.509005669 | AJ6: =IF(MID(G6,2,1)=",",_xlfn.TEXTJOIN(".",FALSE,MID(G6,1,1),MID(G6,3,LEN(G6)-2)),IF(MID(G6,3,1)=",",_xlfn.TEXTJOIN(".",FALSE,MID(G6,1,2),MID(G6,4,LEN(G6)-3)),IF(MID(G6,4,1)=",",_xlfn.TEXTJOIN(".",FALSE,MID(G6,1,3),MID(G6,5,LEN(G6)-4)),IF(MID(G6,5,1)=",",_xlfn.TEXTJOIN(".",FALSE,MID(G6,1,4),MID(G6,6,LEN(G6)-5)),G6)))) -> 18.56367248 | AK6: =IF(MID(H6,2,1)=",",_xlfn.TEXTJOIN(".",FALSE,MID(H6,1,1),MID(H6,3,LEN(H6)-2)),IF(MID(H6,3,1)=",",_xlfn.TEXTJOIN(".",FALSE,MID(H6,1,2),MID(H6,4,LEN(H6)-3)),IF(MID(H6,4,1)=",",_xlfn.TEXTJOIN(".",FALSE,MID(H6,1,3),MID(H6,5,LEN(H6)-4)),IF(MID(H6,5,1)=",",_xlfn.TEXTJOIN(".",FALSE,MID(H6,1,4),MID(H6,6,LEN(H6)-5)),H6)))) -> 12.05466682 | AL6: =IF(MID(I6,2,1)=",",_xlfn.TEXTJOIN(".",FALSE,MID(I6,1,1),MID(I6,3,LEN(I6)-2)),IF(MID(I6,3,1)=",",_xlfn.TEXTJOIN(".",FALSE,MID(I6,1,2),MID(I6,4,LEN(I6)-3)),IF(MID(I6,4,1)=",",_xlfn.TEXTJOIN(".",FALSE,MID(I6,1,3),MID(I6,5,LEN(I6)-4)),IF(MID(I6,5,1)=",",_xlfn.TEXTJOIN(".",FALSE,MID(I6,1,4),MID(I6,6,LEN(I6)-5)),I6)))) -> 261.808516 | AM6: =IF(MID(J6,2,1)=",",_xlfn.TEXTJOIN(".",FALSE,MID(J6,1,1),MID(J6,3,LEN(J6)-2)),IF(MID(J6,3,1)=",",_xlfn.TEXTJOIN(".",FALSE,MID(J6,1,2),MID(J6,4,LEN(J6)-3)),IF(MID(J6,4,1)=",",_xlfn.TEXTJOIN(".",FALSE,MID(J6,1,3),MID(J6,5,LEN(J6)-4)),IF(MID(J6,5,1)=",",_xlfn.TEXTJOIN(".",FALSE,MID(J6,1,4),MID(J6,6,LEN(J6)-5)),J6)))) -> 2682.872187 | AN6: =IF(MID(K6,2,1)=",",_xlfn.TEXTJOIN(".",FALSE,MID(K6,1,1),MID(K6,3,LEN(K6)-2)),IF(MID(K6,3,1)=",",_xlfn.TEXTJOIN(".",FALSE,MID(K6,1,2),MID(K6,4,LEN(K6)-3)),IF(MID(K6,4,1)=",",_xlfn.TEXTJOIN(".",FALSE,MID(K6,1,3),MID(K6,5,LEN(K6)-4)),IF(MID(K6,5,1)=",",_xlfn.TEXTJOIN(".",FALSE,MID(K6,1,4),MID(K6,6,LEN(K6)-5)),K6)))) -> 588.1849822 | AO6: =IF(MID(L6,2,1)=",",_xlfn.TEXTJOIN(".",FALSE,MID(L6,1,1),MID(L6,3,LEN(L6)-2)),IF(MID(L6,3,1)=",",_xlfn.TEXTJOIN(".",FALSE,MID(L6,1,2),MID(L6,4,LEN(L6)-3)),IF(MID(L6,4,1)=",",_xlfn.TEXTJOIN(".",FALSE,MID(L6,1,3),MID(L6,5,LEN(L6)-4)),IF(MID(L6,5,1)=",",_xlfn.TEXTJOIN(".",FALSE,MID(L6,1,4),MID(L6,6,LEN(L6)-5)),L6)))) -> 13.44743243 | AP6: =IF(MID(M6,2,1)=",",_xlfn.TEXTJOIN(".",FALSE,MID(M6,1,1),MID(M6,3,LEN(M6)-2)),IF(MID(M6,3,1)=",",_xlfn.TEXTJOIN(".",FALSE,MID(M6,1,2),MID(M6,4,LEN(M6)-3)),IF(MID(M6,4,1)=",",_xlfn.TEXTJOIN(".",FALSE,MID(M6,1,3),MID(M6,5,LEN(M6)-4)),IF(MID(M6,5,1)=",",_xlfn.TEXTJOIN(".",FALSE,MID(M6,1,4),MID(M6,6,LEN(M6)-5)),M6)))) -> 261.8613074 | ... BJ6: =IF(MID(AG6,2,1)=",",_xlfn.TEXTJOIN(".",FALSE,MID(AG6,1,1),MID(AG6,3,LEN(AG6)-2)),IF(MID(AG6,3,1)=",",_xlfn.TEXTJOIN(".",FALSE,MID(AG6,1,2),MID(AG6,4,LEN(AG6)-3)),IF(MID(AG6,4,1)=",",_xlfn.TEXTJOIN(".",FALSE,MID(AG6,1,3),MID(AG6,5,LEN(AG6)-4)),IF(MID(AG6,5,1)=",",_xlfn.TEXTJOIN(".",FALSE,MID(AG6,1,4),MID(AG6,6,LEN(AG6)-5)),AG6)))) -> 8.196533564
A7: 6 | B7: HK_UK_1-5 | C7: Büro-, Verwaltungs- oder Amtsgebäude | D7: Polizeipräsidium oder -station, Bürogebäude sonstiger Bereitschaftsdienste | E7: 6 | F7: 5.9890125 | G7: 18.866182 | H7: 12.877169 | I7: 267.416 | J7: 2780.8319 | K7: 863.50997 | L7: 13.718263 | M7: 267.416 | N7: 13.301422 | O7: 251.14357 | P7: 0.67259835 | Q7: 0.95934326 | R7: 0.62394733 | S7: 1.3903587 | T7: 0.86820125 | U7: 1.2404127 | V7: 20.452354 | W7: 24.1901 | X7: 3.7823183 | Y7: 19.45588 | Z7: 26.1901 | AA7: 0.35743511 | AB7: 5.5402039 | AC7: 1.4390974 | AD7: 0.1934037 | AE7: 0.90362281 | AF7: 71.953377 | AG7: 6.292867 | AI7: =IF(MID(F7,2,1)=",",_xlfn.TEXTJOIN(".",FALSE,MID(F7,1,1),MID(F7,3,LEN(F7)-2)),IF(MID(F7,3,1)=",",_xlfn.TEXTJOIN(".",FALSE,MID(F7,1,2),MID(F7,4,LEN(F7)-3)),IF(MID(F7,4,1)=",",_xlfn.TEXTJOIN(".",FALSE,MID(F7,1,3),MID(F7,5,LEN(F7)-4)),IF(MID(F7,5,1)=",",_xlfn.TEXTJOIN(".",FALSE,MID(F7,1,4),MID(F7,6,LEN(F7)-5)),F7)))) -> 5.989012537 | AJ7: =IF(MID(G7,2,1)=",",_xlfn.TEXTJOIN(".",FALSE,MID(G7,1,1),MID(G7,3,LEN(G7)-2)),IF(MID(G7,3,1)=",",_xlfn.TEXTJOIN(".",FALSE,MID(G7,1,2),MID(G7,4,LEN(G7)-3)),IF(MID(G7,4,1)=",",_xlfn.TEXTJOIN(".",FALSE,MID(G7,1,3),MID(G7,5,LEN(G7)-4)),IF(MID(G7,5,1)=",",_xlfn.TEXTJOIN(".",FALSE,MID(G7,1,4),MID(G7,6,LEN(G7)-5)),G7)))) -> 18.86618155 | AK7: =IF(MID(H7,2,1)=",",_xlfn.TEXTJOIN(".",FALSE,MID(H7,1,1),MID(H7,3,LEN(H7)-2)),IF(MID(H7,3,1)=",",_xlfn.TEXTJOIN(".",FALSE,MID(H7,1,2),MID(H7,4,LEN(H7)-3)),IF(MID(H7,4,1)=",",_xlfn.TEXTJOIN(".",FALSE,MID(H7,1,3),MID(H7,5,LEN(H7)-4)),IF(MID(H7,5,1)=",",_xlfn.TEXTJOIN(".",FALSE,MID(H7,1,4),MID(H7,6,LEN(H7)-5)),H7)))) -> 12.87716902 | AL7: =IF(MID(I7,2,1)=",",_xlfn.TEXTJOIN(".",FALSE,MID(I7,1,1),MID(I7,3,LEN(I7)-2)),IF(MID(I7,3,1)=",",_xlfn.TEXTJOIN(".",FALSE,MID(I7,1,2),MID(I7,4,LEN(I7)-3)),IF(MID(I7,4,1)=",",_xlfn.TEXTJOIN(".",FALSE,MID(I7,1,3),MID(I7,5,LEN(I7)-4)),IF(MID(I7,5,1)=",",_xlfn.TEXTJOIN(".",FALSE,MID(I7,1,4),MID(I7,6,LEN(I7)-5)),I7)))) -> 267.4160023 | AM7: =IF(MID(J7,2,1)=",",_xlfn.TEXTJOIN(".",FALSE,MID(J7,1,1),MID(J7,3,LEN(J7)-2)),IF(MID(J7,3,1)=",",_xlfn.TEXTJOIN(".",FALSE,MID(J7,1,2),MID(J7,4,LEN(J7)-3)),IF(MID(J7,4,1)=",",_xlfn.TEXTJOIN(".",FALSE,MID(J7,1,3),MID(J7,5,LEN(J7)-4)),IF(MID(J7,5,1)=",",_xlfn.TEXTJOIN(".",FALSE,MID(J7,1,4),MID(J7,6,LEN(J7)-5)),J7)))) -> 2780.831916 | AN7: =IF(MID(K7,2,1)=",",_xlfn.TEXTJOIN(".",FALSE,MID(K7,1,1),MID(K7,3,LEN(K7)-2)),IF(MID(K7,3,1)=",",_xlfn.TEXTJOIN(".",FALSE,MID(K7,1,2),MID(K7,4,LEN(K7)-3)),IF(MID(K7,4,1)=",",_xlfn.TEXTJOIN(".",FALSE,MID(K7,1,3),MID(K7,5,LEN(K7)-4)),IF(MID(K7,5,1)=",",_xlfn.TEXTJOIN(".",FALSE,MID(K7,1,4),MID(K7,6,LEN(K7)-5)),K7)))) -> 863.5099739 | AO7: =IF(MID(L7,2,1)=",",_xlfn.TEXTJOIN(".",FALSE,MID(L7,1,1),MID(L7,3,LEN(L7)-2)),IF(MID(L7,3,1)=",",_xlfn.TEXTJOIN(".",FALSE,MID(L7,1,2),MID(L7,4,LEN(L7)-3)),IF(MID(L7,4,1)=",",_xlfn.TEXTJOIN(".",FALSE,MID(L7,1,3),MID(L7,5,LEN(L7)-4)),IF(MID(L7,5,1)=",",_xlfn.TEXTJOIN(".",FALSE,MID(L7,1,4),MID(L7,6,LEN(L7)-5)),L7)))) -> 13.71826326 | AP7: =IF(MID(M7,2,1)=",",_xlfn.TEXTJOIN(".",FALSE,MID(M7,1,1),MID(M7,3,LEN(M7)-2)),IF(MID(M7,3,1)=",",_xlfn.TEXTJOIN(".",FALSE,MID(M7,1,2),MID(M7,4,LEN(M7)-3)),IF(MID(M7,4,1)=",",_xlfn.TEXTJOIN(".",FALSE,MID(M7,1,3),MID(M7,5,LEN(M7)-4)),IF(MID(M7,5,1)=",",_xlfn.TEXTJOIN(".",FALSE,MID(M7,1,4),MID(M7,6,LEN(M7)-5)),M7)))) -> 267.4160023 | ... BJ7: =IF(MID(AG7,2,1)=",",_xlfn.TEXTJOIN(".",FALSE,MID(AG7,1,1),MID(AG7,3,LEN(AG7)-2)),IF(MID(AG7,3,1)=",",_xlfn.TEXTJOIN(".",FALSE,MID(AG7,1,2),MID(AG7,4,LEN(AG7)-3)),IF(MID(AG7,4,1)=",",_xlfn.TEXTJOIN(".",FALSE,MID(AG7,1,3),MID(AG7,5,LEN(AG7)-4)),IF(MID(AG7,5,1)=",",_xlfn.TEXTJOIN(".",FALSE,MID(AG7,1,4),MID(AG7,6,LEN(AG7)-5)),AG7)))) -> 6.292866971
A8: 7 | B8: HK_UK_2-0 | C8: Gebäude für Forschung und Hochschullehre | E8: 7 | F8: 6.9724412 | G8: 18.090599 | H8: 11.118158 | I8: 246.36088 | J8: 2498.7396 | K8: 273.47039 | L8: 14.409568 | M8: 246.44807 | N8: 12.94519 | O8: 315.98402 | P8: 0.68211788 | Q8: 0.94908092 | R8: 0.57024071 | S8: 1.3402098 | T8: 0.92557657 | U8: 1.1521986 | V8: 21.054945 | W8: 24.03996 | X8: 3.988012 | Y8: 19.914086 | Z8: 26.03996 | AA8: 0.52147852 | AB8: 9.2837163 | AC8: 1.7902098 | AD8: 0.16911486 | AE8: 0.88323541 | AF8: 73.344774 | AG8: 6.2382111 | AI8: =IF(MID(F8,2,1)=",",_xlfn.TEXTJOIN(".",FALSE,MID(F8,1,1),MID(F8,3,LEN(F8)-2)),IF(MID(F8,3,1)=",",_xlfn.TEXTJOIN(".",FALSE,MID(F8,1,2),MID(F8,4,LEN(F8)-3)),IF(MID(F8,4,1)=",",_xlfn.TEXTJOIN(".",FALSE,MID(F8,1,3),MID(F8,5,LEN(F8)-4)),IF(MID(F8,5,1)=",",_xlfn.TEXTJOIN(".",FALSE,MID(F8,1,4),MID(F8,6,LEN(F8)-5)),F8)))) -> 6.972441243 | AJ8: =IF(MID(G8,2,1)=",",_xlfn.TEXTJOIN(".",FALSE,MID(G8,1,1),MID(G8,3,LEN(G8)-2)),IF(MID(G8,3,1)=",",_xlfn.TEXTJOIN(".",FALSE,MID(G8,1,2),MID(G8,4,LEN(G8)-3)),IF(MID(G8,4,1)=",",_xlfn.TEXTJOIN(".",FALSE,MID(G8,1,3),MID(G8,5,LEN(G8)-4)),IF(MID(G8,5,1)=",",_xlfn.TEXTJOIN(".",FALSE,MID(G8,1,4),MID(G8,6,LEN(G8)-5)),G8)))) -> 18.09059894 | AK8: =IF(MID(H8,2,1)=",",_xlfn.TEXTJOIN(".",FALSE,MID(H8,1,1),MID(H8,3,LEN(H8)-2)),IF(MID(H8,3,1)=",",_xlfn.TEXTJOIN(".",FALSE,MID(H8,1,2),MID(H8,4,LEN(H8)-3)),IF(MID(H8,4,1)=",",_xlfn.TEXTJOIN(".",FALSE,MID(H8,1,3),MID(H8,5,LEN(H8)-4)),IF(MID(H8,5,1)=",",_xlfn.TEXTJOIN(".",FALSE,MID(H8,1,4),MID(H8,6,LEN(H8)-5)),H8)))) -> 11.1181577 | AL8: =IF(MID(I8,2,1)=",",_xlfn.TEXTJOIN(".",FALSE,MID(I8,1,1),MID(I8,3,LEN(I8)-2)),IF(MID(I8,3,1)=",",_xlfn.TEXTJOIN(".",FALSE,MID(I8,1,2),MID(I8,4,LEN(I8)-3)),IF(MID(I8,4,1)=",",_xlfn.TEXTJOIN(".",FALSE,MID(I8,1,3),MID(I8,5,LEN(I8)-4)),IF(MID(I8,5,1)=",",_xlfn.TEXTJOIN(".",FALSE,MID(I8,1,4),MID(I8,6,LEN(I8)-5)),I8)))) -> 246.3608795 | AM8: =IF(MID(J8,2,1)=",",_xlfn.TEXTJOIN(".",FALSE,MID(J8,1,1),MID(J8,3,LEN(J8)-2)),IF(MID(J8,3,1)=",",_xlfn.TEXTJOIN(".",FALSE,MID(J8,1,2),MID(J8,4,LEN(J8)-3)),IF(MID(J8,4,1)=",",_xlfn.TEXTJOIN(".",FALSE,MID(J8,1,3),MID(J8,5,LEN(J8)-4)),IF(MID(J8,5,1)=",",_xlfn.TEXTJOIN(".",FALSE,MID(J8,1,4),MID(J8,6,LEN(J8)-5)),J8)))) -> 2498.739613 | AN8: =IF(MID(K8,2,1)=",",_xlfn.TEXTJOIN(".",FALSE,MID(K8,1,1),MID(K8,3,LEN(K8)-2)),IF(MID(K8,3,1)=",",_xlfn.TEXTJOIN(".",FALSE,MID(K8,1,2),MID(K8,4,LEN(K8)-3)),IF(MID(K8,4,1)=",",_xlfn.TEXTJOIN(".",FALSE,MID(K8,1,3),MID(K8,5,LEN(K8)-4)),IF(MID(K8,5,1)=",",_xlfn.TEXTJOIN(".",FALSE,MID(K8,1,4),MID(K8,6,LEN(K8)-5)),K8)))) -> 273.4703942 | AO8: =IF(MID(L8,2,1)=",",_xlfn.TEXTJOIN(".",FALSE,MID(L8,1,1),MID(L8,3,LEN(L8)-2)),IF(MID(L8,3,1)=",",_xlfn.TEXTJOIN(".",FALSE,MID(L8,1,2),MID(L8,4,LEN(L8)-3)),IF(MID(L8,4,1)=",",_xlfn.TEXTJOIN(".",FALSE,MID(L8,1,3),MID(L8,5,LEN(L8)-4)),IF(MID(L8,5,1)=",",_xlfn.TEXTJOIN(".",FALSE,MID(L8,1,4),MID(L8,6,LEN(L8)-5)),L8)))) -> 14.40956838 | AP8: =IF(MID(M8,2,1)=",",_xlfn.TEXTJOIN(".",FALSE,MID(M8,1,1),MID(M8,3,LEN(M8)-2)),IF(MID(M8,3,1)=",",_xlfn.TEXTJOIN(".",FALSE,MID(M8,1,2),MID(M8,4,LEN(M8)-3)),IF(MID(M8,4,1)=",",_xlfn.TEXTJOIN(".",FALSE,MID(M8,1,3),MID(M8,5,LEN(M8)-4)),IF(MID(M8,5,1)=",",_xlfn.TEXTJOIN(".",FALSE,MID(M8,1,4),MID(M8,6,LEN(M8)-5)),M8)))) -> 246.4480667 | ... BJ8: =IF(MID(AG8,2,1)=",",_xlfn.TEXTJOIN(".",FALSE,MID(AG8,1,1),MID(AG8,3,LEN(AG8)-2)),IF(MID(AG8,3,1)=",",_xlfn.TEXTJOIN(".",FALSE,MID(AG8,1,2),MID(AG8,4,LEN(AG8)-3)),IF(MID(AG8,4,1)=",",_xlfn.TEXTJOIN(".",FALSE,MID(AG8,1,3),MID(AG8,5,LEN(AG8)-4)),IF(MID(AG8,5,1)=",",_xlfn.TEXTJOIN(".",FALSE,MID(AG8,1,4),MID(AG8,6,LEN(AG8)-5)),AG8)))) -> 6.238211128
A9: 8 | B9: HK_UK_2-1 | C9: Gebäude für Forschung und Hochschullehre | D9: Hörsaalgebäude | E9: 8 | F9: 7.1136245 | G9: 18.066751 | H9: 10.953127 | I9: 233.70192 | J9: 2360.8908 | K9: 230.31427 | L9: 13.00593 | M9: 233.88565 | N9: 12.878755 | O9: 279.12941 | P9: 0.59358824 | Q9: 0.96249765 | R9: 0.6660634 | S9: 1.4703941 | T9: 0.9284351 | U9: 1.1703875 | V9: 20.997059 | W9: 24.005412 | X9: 4 | Y9: 19.990647 | Z9: 26.005412 | AA9: 0.44541177 | AB9: 10.842512 | AC9: 1.2780735 | AD9: 0.18872768 | AE9: 0.85805424 | AF9: 70.433983 | AG9: 2.3084466 | AI9: =IF(MID(F9,2,1)=",",_xlfn.TEXTJOIN(".",FALSE,MID(F9,1,1),MID(F9,3,LEN(F9)-2)),IF(MID(F9,3,1)=",",_xlfn.TEXTJOIN(".",FALSE,MID(F9,1,2),MID(F9,4,LEN(F9)-3)),IF(MID(F9,4,1)=",",_xlfn.TEXTJOIN(".",FALSE,MID(F9,1,3),MID(F9,5,LEN(F9)-4)),IF(MID(F9,5,1)=",",_xlfn.TEXTJOIN(".",FALSE,MID(F9,1,4),MID(F9,6,LEN(F9)-5)),F9)))) -> 7.11362455 | AJ9: =IF(MID(G9,2,1)=",",_xlfn.TEXTJOIN(".",FALSE,MID(G9,1,1),MID(G9,3,LEN(G9)-2)),IF(MID(G9,3,1)=",",_xlfn.TEXTJOIN(".",FALSE,MID(G9,1,2),MID(G9,4,LEN(G9)-3)),IF(MID(G9,4,1)=",",_xlfn.TEXTJOIN(".",FALSE,MID(G9,1,3),MID(G9,5,LEN(G9)-4)),IF(MID(G9,5,1)=",",_xlfn.TEXTJOIN(".",FALSE,MID(G9,1,4),MID(G9,6,LEN(G9)-5)),G9)))) -> 18.06675122 | AK9: =IF(MID(H9,2,1)=",",_xlfn.TEXTJOIN(".",FALSE,MID(H9,1,1),MID(H9,3,LEN(H9)-2)),IF(MID(H9,3,1)=",",_xlfn.TEXTJOIN(".",FALSE,MID(H9,1,2),MID(H9,4,LEN(H9)-3)),IF(MID(H9,4,1)=",",_xlfn.TEXTJOIN(".",FALSE,MID(H9,1,3),MID(H9,5,LEN(H9)-4)),IF(MID(H9,5,1)=",",_xlfn.TEXTJOIN(".",FALSE,MID(H9,1,4),MID(H9,6,LEN(H9)-5)),H9)))) -> 10.95312667 | AL9: =IF(MID(I9,2,1)=",",_xlfn.TEXTJOIN(".",FALSE,MID(I9,1,1),MID(I9,3,LEN(I9)-2)),IF(MID(I9,3,1)=",",_xlfn.TEXTJOIN(".",FALSE,MID(I9,1,2),MID(I9,4,LEN(I9)-3)),IF(MID(I9,4,1)=",",_xlfn.TEXTJOIN(".",FALSE,MID(I9,1,3),MID(I9,5,LEN(I9)-4)),IF(MID(I9,5,1)=",",_xlfn.TEXTJOIN(".",FALSE,MID(I9,1,4),MID(I9,6,LEN(I9)-5)),I9)))) -> 233.7019193 | AM9: =IF(MID(J9,2,1)=",",_xlfn.TEXTJOIN(".",FALSE,MID(J9,1,1),MID(J9,3,LEN(J9)-2)),IF(MID(J9,3,1)=",",_xlfn.TEXTJOIN(".",FALSE,MID(J9,1,2),MID(J9,4,LEN(J9)-3)),IF(MID(J9,4,1)=",",_xlfn.TEXTJOIN(".",FALSE,MID(J9,1,3),MID(J9,5,LEN(J9)-4)),IF(MID(J9,5,1)=",",_xlfn.TEXTJOIN(".",FALSE,MID(J9,1,4),MID(J9,6,LEN(J9)-5)),J9)))) -> 2360.890751 | AN9: =IF(MID(K9,2,1)=",",_xlfn.TEXTJOIN(".",FALSE,MID(K9,1,1),MID(K9,3,LEN(K9)-2)),IF(MID(K9,3,1)=",",_xlfn.TEXTJOIN(".",FALSE,MID(K9,1,2),MID(K9,4,LEN(K9)-3)),IF(MID(K9,4,1)=",",_xlfn.TEXTJOIN(".",FALSE,MID(K9,1,3),MID(K9,5,LEN(K9)-4)),IF(MID(K9,5,1)=",",_xlfn.TEXTJOIN(".",FALSE,MID(K9,1,4),MID(K9,6,LEN(K9)-5)),K9)))) -> 230.3142725 | AO9: =IF(MID(L9,2,1)=",",_xlfn.TEXTJOIN(".",FALSE,MID(L9,1,1),MID(L9,3,LEN(L9)-2)),IF(MID(L9,3,1)=",",_xlfn.TEXTJOIN(".",FALSE,MID(L9,1,2),MID(L9,4,LEN(L9)-3)),IF(MID(L9,4,1)=",",_xlfn.TEXTJOIN(".",FALSE,MID(L9,1,3),MID(L9,5,LEN(L9)-4)),IF(MID(L9,5,1)=",",_xlfn.TEXTJOIN(".",FALSE,MID(L9,1,4),MID(L9,6,LEN(L9)-5)),L9)))) -> 13.00592991 | AP9: =IF(MID(M9,2,1)=",",_xlfn.TEXTJOIN(".",FALSE,MID(M9,1,1),MID(M9,3,LEN(M9)-2)),IF(MID(M9,3,1)=",",_xlfn.TEXTJOIN(".",FALSE,MID(M9,1,2),MID(M9,4,LEN(M9)-3)),IF(MID(M9,4,1)=",",_xlfn.TEXTJOIN(".",FALSE,MID(M9,1,3),MID(M9,5,LEN(M9)-4)),IF(MID(M9,5,1)=",",_xlfn.TEXTJOIN(".",FALSE,MID(M9,1,4),MID(M9,6,LEN(M9)-5)),M9)))) -> 233.8856536 | ... BJ9: =IF(MID(AG9,2,1)=",",_xlfn.TEXTJOIN(".",FALSE,MID(AG9,1,1),MID(AG9,3,LEN(AG9)-2)),IF(MID(AG9,3,1)=",",_xlfn.TEXTJOIN(".",FALSE,MID(AG9,1,2),MID(AG9,4,LEN(AG9)-3)),IF(MID(AG9,4,1)=",",_xlfn.TEXTJOIN(".",FALSE,MID(AG9,1,3),MID(AG9,5,LEN(AG9)-4)),IF(MID(AG9,5,1)=",",_xlfn.TEXTJOIN(".",FALSE,MID(AG9,1,4),MID(AG9,6,LEN(AG9)-5)),AG9)))) -> 2.308446608
A10: 9 | B10: HK_UK_2-2 | C10: Gebäude für Forschung und Hochschullehre | D10: Verwaltungs- oder Seminargebäude | E10: 9 | F10: 7.0247036 | G10: 18.071591 | H10: 11.046888 | I10: 248.23164 | J10: 2509.8245 | K10: 254.13703 | L10: 14.101351 | M10: 248.31787 | N10: 12.905724 | O10: 322.8 | P10: 0.6856 | Q10: 0.94384 | R10: 0.55282429 | S10: 1.31795 | T10: 0.92295011 | U10: 1.1411657 | V10: 20.966 | W10: 24.08 | X10: 3.992 | Y10: 19.856 | Z10: 26.08 | AA10: 0.537 | AB10: 8.1978 | AC10: 1.7615 | AD10: 0.18498661 | AE10: 0.87096115 | AF10: 73.349398 | AG10: 6.3847132 | AI10: =IF(MID(F10,2,1)=",",_xlfn.TEXTJOIN(".",FALSE,MID(F10,1,1),MID(F10,3,LEN(F10)-2)),IF(MID(F10,3,1)=",",_xlfn.TEXTJOIN(".",FALSE,MID(F10,1,2),MID(F10,4,LEN(F10)-3)),IF(MID(F10,4,1)=",",_xlfn.TEXTJOIN(".",FALSE,MID(F10,1,3),MID(F10,5,LEN(F10)-4)),IF(MID(F10,5,1)=",",_xlfn.TEXTJOIN(".",FALSE,MID(F10,1,4),MID(F10,6,LEN(F10)-5)),F10)))) -> 7.024703624 | AJ10: =IF(MID(G10,2,1)=",",_xlfn.TEXTJOIN(".",FALSE,MID(G10,1,1),MID(G10,3,LEN(G10)-2)),IF(MID(G10,3,1)=",",_xlfn.TEXTJOIN(".",FALSE,MID(G10,1,2),MID(G10,4,LEN(G10)-3)),IF(MID(G10,4,1)=",",_xlfn.TEXTJOIN(".",FALSE,MID(G10,1,3),MID(G10,5,LEN(G10)-4)),IF(MID(G10,5,1)=",",_xlfn.TEXTJOIN(".",FALSE,MID(G10,1,4),MID(G10,6,LEN(G10)-5)),G10)))) -> 18.07159139 | AK10: =IF(MID(H10,2,1)=",",_xlfn.TEXTJOIN(".",FALSE,MID(H10,1,1),MID(H10,3,LEN(H10)-2)),IF(MID(H10,3,1)=",",_xlfn.TEXTJOIN(".",FALSE,MID(H10,1,2),MID(H10,4,LEN(H10)-3)),IF(MID(H10,4,1)=",",_xlfn.TEXTJOIN(".",FALSE,MID(H10,1,3),MID(H10,5,LEN(H10)-4)),IF(MID(H10,5,1)=",",_xlfn.TEXTJOIN(".",FALSE,MID(H10,1,4),MID(H10,6,LEN(H10)-5)),H10)))) -> 11.04688777 | AL10: =IF(MID(I10,2,1)=",",_xlfn.TEXTJOIN(".",FALSE,MID(I10,1,1),MID(I10,3,LEN(I10)-2)),IF(MID(I10,3,1)=",",_xlfn.TEXTJOIN(".",FALSE,MID(I10,1,2),MID(I10,4,LEN(I10)-3)),IF(MID(I10,4,1)=",",_xlfn.TEXTJOIN(".",FALSE,MID(I10,1,3),MID(I10,5,LEN(I10)-4)),IF(MID(I10,5,1)=",",_xlfn.TEXTJOIN(".",FALSE,MID(I10,1,4),MID(I10,6,LEN(I10)-5)),I10)))) -> 248.2316419 | AM10: =IF(MID(J10,2,1)=",",_xlfn.TEXTJOIN(".",FALSE,MID(J10,1,1),MID(J10,3,LEN(J10)-2)),IF(MID(J10,3,1)=",",_xlfn.TEXTJOIN(".",FALSE,MID(J10,1,2),MID(J10,4,LEN(J10)-3)),IF(MID(J10,4,1)=",",_xlfn.TEXTJOIN(".",FALSE,MID(J10,1,3),MID(J10,5,LEN(J10)-4)),IF(MID(J10,5,1)=",",_xlfn.TEXTJOIN(".",FALSE,MID(J10,1,4),MID(J10,6,LEN(J10)-5)),J10)))) -> 2509.824548 | AN10: =IF(MID(K10,2,1)=",",_xlfn.TEXTJOIN(".",FALSE,MID(K10,1,1),MID(K10,3,LEN(K10)-2)),IF(MID(K10,3,1)=",",_xlfn.TEXTJOIN(".",FALSE,MID(K10,1,2),MID(K10,4,LEN(K10)-3)),IF(MID(K10,4,1)=",",_xlfn.TEXTJOIN(".",FALSE,MID(K10,1,3),MID(K10,5,LEN(K10)-4)),IF(MID(K10,5,1)=",",_xlfn.TEXTJOIN(".",FALSE,MID(K10,1,4),MID(K10,6,LEN(K10)-5)),K10)))) -> 254.1370303 | AO10: =IF(MID(L10,2,1)=",",_xlfn.TEXTJOIN(".",FALSE,MID(L10,1,1),MID(L10,3,LEN(L10)-2)),IF(MID(L10,3,1)=",",_xlfn.TEXTJOIN(".",FALSE,MID(L10,1,2),MID(L10,4,LEN(L10)-3)),IF(MID(L10,4,1)=",",_xlfn.TEXTJOIN(".",FALSE,MID(L10,1,3),MID(L10,5,LEN(L10)-4)),IF(MID(L10,5,1)=",",_xlfn.TEXTJOIN(".",FALSE,MID(L10,1,4),MID(L10,6,LEN(L10)-5)),L10)))) -> 14.10135149 | AP10: =IF(MID(M10,2,1)=",",_xlfn.TEXTJOIN(".",FALSE,MID(M10,1,1),MID(M10,3,LEN(M10)-2)),IF(MID(M10,3,1)=",",_xlfn.TEXTJOIN(".",FALSE,MID(M10,1,2),MID(M10,4,LEN(M10)-3)),IF(MID(M10,4,1)=",",_xlfn.TEXTJOIN(".",FALSE,MID(M10,1,3),MID(M10,5,LEN(M10)-4)),IF(MID(M10,5,1)=",",_xlfn.TEXTJOIN(".",FALSE,MID(M10,1,4),MID(M10,6,LEN(M10)-5)),M10)))) -> 248.317874 | ... BJ10: =IF(MID(AG10,2,1)=",",_xlfn.TEXTJOIN(".",FALSE,MID(AG10,1,1),MID(AG10,3,LEN(AG10)-2)),IF(MID(AG10,3,1)=",",_xlfn.TEXTJOIN(".",FALSE,MID(AG10,1,2),MID(AG10,4,LEN(AG10)-3)),IF(MID(AG10,4,1)=",",_xlfn.TEXTJOIN(".",FALSE,MID(AG10,1,3),MID(AG10,5,LEN(AG10)-4)),IF(MID(AG10,5,1)=",",_xlfn.TEXTJOIN(".",FALSE,MID(AG10,1,4),MID(AG10,6,LEN(AG10)-5)),AG10)))) -> 6.384713193
A11: 10 | B11: HK_UK_2-3 | C11: Gebäude für Forschung und Hochschullehre | D11: Institutsgebäude für Forschung und Lehre (Labor mit geringen Anforderungen an die Raumlufttechnik, z.B. Medizin, Informatik) | E11: 10 | F11: 7.0603358 | G11: 18.058201 | H11: 10.997865 | I11: 243.67856 | J11: 2461.527 | K11: 241.96587 | L11: 13.831304 | M11: 243.76765 | N11: 12.877994 | O11: 318.52783 | P11: 0.66446713 | Q11: 0.94839924 | R11: 0.57180455 | S11: 1.3681261 | T11: 0.91671281 | U11: 1.1448537 | V11: 20.993405 | W11: 24.047154 | X11: 3.9952048 | Y11: 19.900286 | Z11: 26.047154 | AA11: 0.52568352 | AB11: 9.1891632 | AC11: 1.6911292 | AD11: 0.19085367 | AE11: 0.86456136 | AF11: 72.517487 | AG11: 5.3806301 | AI11: =IF(MID(F11,2,1)=",",_xlfn.TEXTJOIN(".",FALSE,MID(F11,1,1),MID(F11,3,LEN(F11)-2)),IF(MID(F11,3,1)=",",_xlfn.TEXTJOIN(".",FALSE,MID(F11,1,2),MID(F11,4,LEN(F11)-3)),IF(MID(F11,4,1)=",",_xlfn.TEXTJOIN(".",FALSE,MID(F11,1,3),MID(F11,5,LEN(F11)-4)),IF(MID(F11,5,1)=",",_xlfn.TEXTJOIN(".",FALSE,MID(F11,1,4),MID(F11,6,LEN(F11)-5)),F11)))) -> 7.060335768 | AJ11: =IF(MID(G11,2,1)=",",_xlfn.TEXTJOIN(".",FALSE,MID(G11,1,1),MID(G11,3,LEN(G11)-2)),IF(MID(G11,3,1)=",",_xlfn.TEXTJOIN(".",FALSE,MID(G11,1,2),MID(G11,4,LEN(G11)-3)),IF(MID(G11,4,1)=",",_xlfn.TEXTJOIN(".",FALSE,MID(G11,1,3),MID(G11,5,LEN(G11)-4)),IF(MID(G11,5,1)=",",_xlfn.TEXTJOIN(".",FALSE,MID(G11,1,4),MID(G11,6,LEN(G11)-5)),G11)))) -> 18.05820108 | AK11: =IF(MID(H11,2,1)=",",_xlfn.TEXTJOIN(".",FALSE,MID(H11,1,1),MID(H11,3,LEN(H11)-2)),IF(MID(H11,3,1)=",",_xlfn.TEXTJOIN(".",FALSE,MID(H11,1,2),MID(H11,4,LEN(H11)-3)),IF(MID(H11,4,1)=",",_xlfn.TEXTJOIN(".",FALSE,MID(H11,1,3),MID(H11,5,LEN(H11)-4)),IF(MID(H11,5,1)=",",_xlfn.TEXTJOIN(".",FALSE,MID(H11,1,4),MID(H11,6,LEN(H11)-5)),H11)))) -> 10.99786532 | AL11: =IF(MID(I11,2,1)=",",_xlfn.TEXTJOIN(".",FALSE,MID(I11,1,1),MID(I11,3,LEN(I11)-2)),IF(MID(I11,3,1)=",",_xlfn.TEXTJOIN(".",FALSE,MID(I11,1,2),MID(I11,4,LEN(I11)-3)),IF(MID(I11,4,1)=",",_xlfn.TEXTJOIN(".",FALSE,MID(I11,1,3),MID(I11,5,LEN(I11)-4)),IF(MID(I11,5,1)=",",_xlfn.TEXTJOIN(".",FALSE,MID(I11,1,4),MID(I11,6,LEN(I11)-5)),I11)))) -> 243.6785592 | AM11: =IF(MID(J11,2,1)=",",_xlfn.TEXTJOIN(".",FALSE,MID(J11,1,1),MID(J11,3,LEN(J11)-2)),IF(MID(J11,3,1)=",",_xlfn.TEXTJOIN(".",FALSE,MID(J11,1,2),MID(J11,4,LEN(J11)-3)),IF(MID(J11,4,1)=",",_xlfn.TEXTJOIN(".",FALSE,MID(J11,1,3),MID(J11,5,LEN(J11)-4)),IF(MID(J11,5,1)=",",_xlfn.TEXTJOIN(".",FALSE,MID(J11,1,4),MID(J11,6,LEN(J11)-5)),J11)))) -> 2461.527028 | AN11: =IF(MID(K11,2,1)=",",_xlfn.TEXTJOIN(".",FALSE,MID(K11,1,1),MID(K11,3,LEN(K11)-2)),IF(MID(K11,3,1)=",",_xlfn.TEXTJOIN(".",FALSE,MID(K11,1,2),MID(K11,4,LEN(K11)-3)),IF(MID(K11,4,1)=",",_xlfn.TEXTJOIN(".",FALSE,MID(K11,1,3),MID(K11,5,LEN(K11)-4)),IF(MID(K11,5,1)=",",_xlfn.TEXTJOIN(".",FALSE,MID(K11,1,4),MID(K11,6,LEN(K11)-5)),K11)))) -> 241.9658693 | AO11: =IF(MID(L11,2,1)=",",_xlfn.TEXTJOIN(".",FALSE,MID(L11,1,1),MID(L11,3,LEN(L11)-2)),IF(MID(L11,3,1)=",",_xlfn.TEXTJOIN(".",FALSE,MID(L11,1,2),MID(L11,4,LEN(L11)-3)),IF(MID(L11,4,1)=",",_xlfn.TEXTJOIN(".",FALSE,MID(L11,1,3),MID(L11,5,LEN(L11)-4)),IF(MID(L11,5,1)=",",_xlfn.TEXTJOIN(".",FALSE,MID(L11,1,4),MID(L11,6,LEN(L11)-5)),L11)))) -> 13.83130363 | AP11: =IF(MID(M11,2,1)=",",_xlfn.TEXTJOIN(".",FALSE,MID(M11,1,1),MID(M11,3,LEN(M11)-2)),IF(MID(M11,3,1)=",",_xlfn.TEXTJOIN(".",FALSE,MID(M11,1,2),MID(M11,4,LEN(M11)-3)),IF(MID(M11,4,1)=",",_xlfn.TEXTJOIN(".",FALSE,MID(M11,1,3),MID(M11,5,LEN(M11)-4)),IF(MID(M11,5,1)=",",_xlfn.TEXTJOIN(".",FALSE,MID(M11,1,4),MID(M11,6,LEN(M11)-5)),M11)))) -> 243.7676498 | ... BJ11: =IF(MID(AG11,2,1)=",",_xlfn.TEXTJOIN(".",FALSE,MID(AG11,1,1),MID(AG11,3,LEN(AG11)-2)),IF(MID(AG11,3,1)=",",_xlfn.TEXTJOIN(".",FALSE,MID(AG11,1,2),MID(AG11,4,LEN(AG11)-3)),IF(MID(AG11,4,1)=",",_xlfn.TEXTJOIN(".",FALSE,MID(AG11,1,3),MID(AG11,5,LEN(AG11)-4)),IF(MID(AG11,5,1)=",",_xlfn.TEXTJOIN(".",FALSE,MID(AG11,1,4),MID(AG11,6,LEN(AG11)-5)),AG11)))) -> 5.380630057
A12: 11 | B12: HK_UK_2-4 | C12: Gebäude für Forschung und Hochschullehre | D12: Institutsgebäude für Forschung und Lehre (Labor mit hohen Anforderungen an die Raumlufttechnik, z.B. Chemie, Tierforschung) | E12: 11 | F12: 6.9863457 | G12: 17.952531 | H12: 10.966185 | I12: 249.32459 | J12: 2525.5866 | K12: 215.55402 | L12: 15.64878 | M12: 249.32459 | N12: 12.878111 | O12: 304.004 | P12: 0.70650651 | Q12: 0.94955956 | R12: 0.59483225 | S12: 1.2293293 | T12: 0.95693926 | U12: 1.2109736 | V12: 21.149149 | W12: 24.044044 | X12: 3.987988 | Y12: 19.868869 | Z12: 26.044044 | AA12: 0.46446446 | AB12: 8.6904905 | AC12: 1.9169169 | AD12: 0.10063661 | AE12: 0.92366039 | AF12: 75.899611 | AG12: 7.3995003 | AI12: =IF(MID(F12,2,1)=",",_xlfn.TEXTJOIN(".",FALSE,MID(F12,1,1),MID(F12,3,LEN(F12)-2)),IF(MID(F12,3,1)=",",_xlfn.TEXTJOIN(".",FALSE,MID(F12,1,2),MID(F12,4,LEN(F12)-3)),IF(MID(F12,4,1)=",",_xlfn.TEXTJOIN(".",FALSE,MID(F12,1,3),MID(F12,5,LEN(F12)-4)),IF(MID(F12,5,1)=",",_xlfn.TEXTJOIN(".",FALSE,MID(F12,1,4),MID(F12,6,LEN(F12)-5)),F12)))) -> 6.986345731 | AJ12: =IF(MID(G12,2,1)=",",_xlfn.TEXTJOIN(".",FALSE,MID(G12,1,1),MID(G12,3,LEN(G12)-2)),IF(MID(G12,3,1)=",",_xlfn.TEXTJOIN(".",FALSE,MID(G12,1,2),MID(G12,4,LEN(G12)-3)),IF(MID(G12,4,1)=",",_xlfn.TEXTJOIN(".",FALSE,MID(G12,1,3),MID(G12,5,LEN(G12)-4)),IF(MID(G12,5,1)=",",_xlfn.TEXTJOIN(".",FALSE,MID(G12,1,4),MID(G12,6,LEN(G12)-5)),G12)))) -> 17.95253095 | AK12: =IF(MID(H12,2,1)=",",_xlfn.TEXTJOIN(".",FALSE,MID(H12,1,1),MID(H12,3,LEN(H12)-2)),IF(MID(H12,3,1)=",",_xlfn.TEXTJOIN(".",FALSE,MID(H12,1,2),MID(H12,4,LEN(H12)-3)),IF(MID(H12,4,1)=",",_xlfn.TEXTJOIN(".",FALSE,MID(H12,1,3),MID(H12,5,LEN(H12)-4)),IF(MID(H12,5,1)=",",_xlfn.TEXTJOIN(".",FALSE,MID(H12,1,4),MID(H12,6,LEN(H12)-5)),H12)))) -> 10.96618521 | AL12: =IF(MID(I12,2,1)=",",_xlfn.TEXTJOIN(".",FALSE,MID(I12,1,1),MID(I12,3,LEN(I12)-2)),IF(MID(I12,3,1)=",",_xlfn.TEXTJOIN(".",FALSE,MID(I12,1,2),MID(I12,4,LEN(I12)-3)),IF(MID(I12,4,1)=",",_xlfn.TEXTJOIN(".",FALSE,MID(I12,1,3),MID(I12,5,LEN(I12)-4)),IF(MID(I12,5,1)=",",_xlfn.TEXTJOIN(".",FALSE,MID(I12,1,4),MID(I12,6,LEN(I12)-5)),I12)))) -> 249.3245895 | AM12: =IF(MID(J12,2,1)=",",_xlfn.TEXTJOIN(".",FALSE,MID(J12,1,1),MID(J12,3,LEN(J12)-2)),IF(MID(J12,3,1)=",",_xlfn.TEXTJOIN(".",FALSE,MID(J12,1,2),MID(J12,4,LEN(J12)-3)),IF(MID(J12,4,1)=",",_xlfn.TEXTJOIN(".",FALSE,MID(J12,1,3),MID(J12,5,LEN(J12)-4)),IF(MID(J12,5,1)=",",_xlfn.TEXTJOIN(".",FALSE,MID(J12,1,4),MID(J12,6,LEN(J12)-5)),J12)))) -> 2525.586636 | AN12: =IF(MID(K12,2,1)=",",_xlfn.TEXTJOIN(".",FALSE,MID(K12,1,1),MID(K12,3,LEN(K12)-2)),IF(MID(K12,3,1)=",",_xlfn.TEXTJOIN(".",FALSE,MID(K12,1,2),MID(K12,4,LEN(K12)-3)),IF(MID(K12,4,1)=",",_xlfn.TEXTJOIN(".",FALSE,MID(K12,1,3),MID(K12,5,LEN(K12)-4)),IF(MID(K12,5,1)=",",_xlfn.TEXTJOIN(".",FALSE,MID(K12,1,4),MID(K12,6,LEN(K12)-5)),K12)))) -> 215.5540233 | AO12: =IF(MID(L12,2,1)=",",_xlfn.TEXTJOIN(".",FALSE,MID(L12,1,1),MID(L12,3,LEN(L12)-2)),IF(MID(L12,3,1)=",",_xlfn.TEXTJOIN(".",FALSE,MID(L12,1,2),MID(L12,4,LEN(L12)-3)),IF(MID(L12,4,1)=",",_xlfn.TEXTJOIN(".",FALSE,MID(L12,1,3),MID(L12,5,LEN(L12)-4)),IF(MID(L12,5,1)=",",_xlfn.TEXTJOIN(".",FALSE,MID(L12,1,4),MID(L12,6,LEN(L12)-5)),L12)))) -> 15.6487799 | AP12: =IF(MID(M12,2,1)=",",_xlfn.TEXTJOIN(".",FALSE,MID(M12,1,1),MID(M12,3,LEN(M12)-2)),IF(MID(M12,3,1)=",",_xlfn.TEXTJOIN(".",FALSE,MID(M12,1,2),MID(M12,4,LEN(M12)-3)),IF(MID(M12,4,1)=",",_xlfn.TEXTJOIN(".",FALSE,MID(M12,1,3),MID(M12,5,LEN(M12)-4)),IF(MID(M12,5,1)=",",_xlfn.TEXTJOIN(".",FALSE,MID(M12,1,4),MID(M12,6,LEN(M12)-5)),M12)))) -> 249.3245895 | ... BJ12: =IF(MID(AG12,2,1)=",",_xlfn.TEXTJOIN(".",FALSE,MID(AG12,1,1),MID(AG12,3,LEN(AG12)-2)),IF(MID(AG12,3,1)=",",_xlfn.TEXTJOIN(".",FALSE,MID(AG12,1,2),MID(AG12,4,LEN(AG12)-3)),IF(MID(AG12,4,1)=",",_xlfn.TEXTJOIN(".",FALSE,MID(AG12,1,3),MID(AG12,5,LEN(AG12)-4)),IF(MID(AG12,5,1)=",",_xlfn.TEXTJOIN(".",FALSE,MID(AG12,1,4),MID(AG12,6,LEN(AG12)-5)),AG12)))) -> 7.399500272
A13: 12 | B13: HK_UK_2-5 | C13: Gebäude für Forschung und Hochschullehre | D13: Bürogebäude von Forschungsanstalten ohne Lehre | E13: 12 | F13: 6.5179404 | G13: 18.447968 | H13: 11.930027 | I13: 257.90423 | J13: 2664.9745 | K13: 515.21217 | L13: 15.747249 | M13: 257.90423 | N13: 13.343689 | O13: 314.28571 | P13: 0.74205794 | Q13: 0.94933067 | R13: 0.53144797 | S13: 1.2485514 | T13: 0.93902341 | U13: 1.1464579 | V13: 21.288711 | W13: 24 | X13: 3.9080919 | Y13: 20.045954 | Z13: 26 | AA13: 0.55544456 | AB13: 9.8848651 | AC13: 2.1253746 | AD13: 0.13692896 | AE13: 0.91875635 | AF13: 74.417782 | AG13: 7.3050435 | AI13: =IF(MID(F13,2,1)=",",_xlfn.TEXTJOIN(".",FALSE,MID(F13,1,1),MID(F13,3,LEN(F13)-2)),IF(MID(F13,3,1)=",",_xlfn.TEXTJOIN(".",FALSE,MID(F13,1,2),MID(F13,4,LEN(F13)-3)),IF(MID(F13,4,1)=",",_xlfn.TEXTJOIN(".",FALSE,MID(F13,1,3),MID(F13,5,LEN(F13)-4)),IF(MID(F13,5,1)=",",_xlfn.TEXTJOIN(".",FALSE,MID(F13,1,4),MID(F13,6,LEN(F13)-5)),F13)))) -> 6.517940435 | AJ13: =IF(MID(G13,2,1)=",",_xlfn.TEXTJOIN(".",FALSE,MID(G13,1,1),MID(G13,3,LEN(G13)-2)),IF(MID(G13,3,1)=",",_xlfn.TEXTJOIN(".",FALSE,MID(G13,1,2),MID(G13,4,LEN(G13)-3)),IF(MID(G13,4,1)=",",_xlfn.TEXTJOIN(".",FALSE,MID(G13,1,3),MID(G13,5,LEN(G13)-4)),IF(MID(G13,5,1)=",",_xlfn.TEXTJOIN(".",FALSE,MID(G13,1,4),MID(G13,6,LEN(G13)-5)),G13)))) -> 18.44796786 | AK13: =IF(MID(H13,2,1)=",",_xlfn.TEXTJOIN(".",FALSE,MID(H13,1,1),MID(H13,3,LEN(H13)-2)),IF(MID(H13,3,1)=",",_xlfn.TEXTJOIN(".",FALSE,MID(H13,1,2),MID(H13,4,LEN(H13)-3)),IF(MID(H13,4,1)=",",_xlfn.TEXTJOIN(".",FALSE,MID(H13,1,3),MID(H13,5,LEN(H13)-4)),IF(MID(H13,5,1)=",",_xlfn.TEXTJOIN(".",FALSE,MID(H13,1,4),MID(H13,6,LEN(H13)-5)),H13)))) -> 11.93002743 | AL13: =IF(MID(I13,2,1)=",",_xlfn.TEXTJOIN(".",FALSE,MID(I13,1,1),MID(I13,3,LEN(I13)-2)),IF(MID(I13,3,1)=",",_xlfn.TEXTJOIN(".",FALSE,MID(I13,1,2),MID(I13,4,LEN(I13)-3)),IF(MID(I13,4,1)=",",_xlfn.TEXTJOIN(".",FALSE,MID(I13,1,3),MID(I13,5,LEN(I13)-4)),IF(MID(I13,5,1)=",",_xlfn.TEXTJOIN(".",FALSE,MID(I13,1,4),MID(I13,6,LEN(I13)-5)),I13)))) -> 257.9042341 | AM13: =IF(MID(J13,2,1)=",",_xlfn.TEXTJOIN(".",FALSE,MID(J13,1,1),MID(J13,3,LEN(J13)-2)),IF(MID(J13,3,1)=",",_xlfn.TEXTJOIN(".",FALSE,MID(J13,1,2),MID(J13,4,LEN(J13)-3)),IF(MID(J13,4,1)=",",_xlfn.TEXTJOIN(".",FALSE,MID(J13,1,3),MID(J13,5,LEN(J13)-4)),IF(MID(J13,5,1)=",",_xlfn.TEXTJOIN(".",FALSE,MID(J13,1,4),MID(J13,6,LEN(J13)-5)),J13)))) -> 2664.974478 | AN13: =IF(MID(K13,2,1)=",",_xlfn.TEXTJOIN(".",FALSE,MID(K13,1,1),MID(K13,3,LEN(K13)-2)),IF(MID(K13,3,1)=",",_xlfn.TEXTJOIN(".",FALSE,MID(K13,1,2),MID(K13,4,LEN(K13)-3)),IF(MID(K13,4,1)=",",_xlfn.TEXTJOIN(".",FALSE,MID(K13,1,3),MID(K13,5,LEN(K13)-4)),IF(MID(K13,5,1)=",",_xlfn.TEXTJOIN(".",FALSE,MID(K13,1,4),MID(K13,6,LEN(K13)-5)),K13)))) -> 515.2121664 | AO13: =IF(MID(L13,2,1)=",",_xlfn.TEXTJOIN(".",FALSE,MID(L13,1,1),MID(L13,3,LEN(L13)-2)),IF(MID(L13,3,1)=",",_xlfn.TEXTJOIN(".",FALSE,MID(L13,1,2),MID(L13,4,LEN(L13)-3)),IF(MID(L13,4,1)=",",_xlfn.TEXTJOIN(".",FALSE,MID(L13,1,3),MID(L13,5,LEN(L13)-4)),IF(MID(L13,5,1)=",",_xlfn.TEXTJOIN(".",FALSE,MID(L13,1,4),MID(L13,6,LEN(L13)-5)),L13)))) -> 15.74724882 | AP13: =IF(MID(M13,2,1)=",",_xlfn.TEXTJOIN(".",FALSE,MID(M13,1,1),MID(M13,3,LEN(M13)-2)),IF(MID(M13,3,1)=",",_xlfn.TEXTJOIN(".",FALSE,MID(M13,1,2),MID(M13,4,LEN(M13)-3)),IF(MID(M13,4,1)=",",_xlfn.TEXTJOIN(".",FALSE,MID(M13,1,3),MID(M13,5,LEN(M13)-4)),IF(MID(M13,5,1)=",",_xlfn.TEXTJOIN(".",FALSE,MID(M13,1,4),MID(M13,6,LEN(M13)-5)),M13)))) -> 257.9042341 | ... BJ13: =IF(MID(AG13,2,1)=",",_xlfn.TEXTJOIN(".",FALSE,MID(AG13,1,1),MID(AG13,3,LEN(AG13)-2)),IF(MID(AG13,3,1)=",",_xlfn.TEXTJOIN(".",FALSE,MID(AG13,1,2),MID(AG13,4,LEN(AG13)-3)),IF(MID(AG13,4,1)=",",_xlfn.TEXTJOIN(".",FALSE,MID(AG13,1,3),MID(AG13,5,LEN(AG13)-4)),IF(MID(AG13,5,1)=",",_xlfn.TEXTJOIN(".",FALSE,MID(AG13,1,4),MID(AG13,6,LEN(AG13)-5)),AG13)))) -> 7.305043502
A14: 13 | B14: HK_UK_2-6 | C14: Gebäude für Forschung und Hochschullehre | D14: Laborgebäude von Forschungsanstalten und Unternehmen (Labor mit geringen Anforderungen an die Raumlufttechnik) | E14: 13 | F14: 6.9437404 | G14: 18.009063 | H14: 11.065323 | I14: 250.2926 | J14: 2541.5516 | K14: 243.87388 | L14: 16.196442 | M14: 250.2926 | N14: 12.942134 | O14: 303.4965 | P14: 0.73486513 | Q14: 0.95314685 | R14: 0.58210478 | S14: 1.2662837 | T14: 0.96171822 | U14: 1.1888591 | V14: 21.237762 | W14: 24.01998 | X14: 4 | Y14: 19.919081 | Z14: 26.01998 | AA14: 0.49150849 | AB14: 9.4403596 | AC14: 2.1128871 | AD14: 0.091635038 | AE14: 0.94816419 | AF14: 76.417955 | AG14: 8.4765429 | AI14: =IF(MID(F14,2,1)=",",_xlfn.TEXTJOIN(".",FALSE,MID(F14,1,1),MID(F14,3,LEN(F14)-2)),IF(MID(F14,3,1)=",",_xlfn.TEXTJOIN(".",FALSE,MID(F14,1,2),MID(F14,4,LEN(F14)-3)),IF(MID(F14,4,1)=",",_xlfn.TEXTJOIN(".",FALSE,MID(F14,1,3),MID(F14,5,LEN(F14)-4)),IF(MID(F14,5,1)=",",_xlfn.TEXTJOIN(".",FALSE,MID(F14,1,4),MID(F14,6,LEN(F14)-5)),F14)))) -> 6.943740434 | AJ14: =IF(MID(G14,2,1)=",",_xlfn.TEXTJOIN(".",FALSE,MID(G14,1,1),MID(G14,3,LEN(G14)-2)),IF(MID(G14,3,1)=",",_xlfn.TEXTJOIN(".",FALSE,MID(G14,1,2),MID(G14,4,LEN(G14)-3)),IF(MID(G14,4,1)=",",_xlfn.TEXTJOIN(".",FALSE,MID(G14,1,3),MID(G14,5,LEN(G14)-4)),IF(MID(G14,5,1)=",",_xlfn.TEXTJOIN(".",FALSE,MID(G14,1,4),MID(G14,6,LEN(G14)-5)),G14)))) -> 18.00906305 | AK14: =IF(MID(H14,2,1)=",",_xlfn.TEXTJOIN(".",FALSE,MID(H14,1,1),MID(H14,3,LEN(H14)-2)),IF(MID(H14,3,1)=",",_xlfn.TEXTJOIN(".",FALSE,MID(H14,1,2),MID(H14,4,LEN(H14)-3)),IF(MID(H14,4,1)=",",_xlfn.TEXTJOIN(".",FALSE,MID(H14,1,3),MID(H14,5,LEN(H14)-4)),IF(MID(H14,5,1)=",",_xlfn.TEXTJOIN(".",FALSE,MID(H14,1,4),MID(H14,6,LEN(H14)-5)),H14)))) -> 11.06532261 | AL14: =IF(MID(I14,2,1)=",",_xlfn.TEXTJOIN(".",FALSE,MID(I14,1,1),MID(I14,3,LEN(I14)-2)),IF(MID(I14,3,1)=",",_xlfn.TEXTJOIN(".",FALSE,MID(I14,1,2),MID(I14,4,LEN(I14)-3)),IF(MID(I14,4,1)=",",_xlfn.TEXTJOIN(".",FALSE,MID(I14,1,3),MID(I14,5,LEN(I14)-4)),IF(MID(I14,5,1)=",",_xlfn.TEXTJOIN(".",FALSE,MID(I14,1,4),MID(I14,6,LEN(I14)-5)),I14)))) -> 250.2926038 | AM14: =IF(MID(J14,2,1)=",",_xlfn.TEXTJOIN(".",FALSE,MID(J14,1,1),MID(J14,3,LEN(J14)-2)),IF(MID(J14,3,1)=",",_xlfn.TEXTJOIN(".",FALSE,MID(J14,1,2),MID(J14,4,LEN(J14)-3)),IF(MID(J14,4,1)=",",_xlfn.TEXTJOIN(".",FALSE,MID(J14,1,3),MID(J14,5,LEN(J14)-4)),IF(MID(J14,5,1)=",",_xlfn.TEXTJOIN(".",FALSE,MID(J14,1,4),MID(J14,6,LEN(J14)-5)),J14)))) -> 2541.551637 | AN14: =IF(MID(K14,2,1)=",",_xlfn.TEXTJOIN(".",FALSE,MID(K14,1,1),MID(K14,3,LEN(K14)-2)),IF(MID(K14,3,1)=",",_xlfn.TEXTJOIN(".",FALSE,MID(K14,1,2),MID(K14,4,LEN(K14)-3)),IF(MID(K14,4,1)=",",_xlfn.TEXTJOIN(".",FALSE,MID(K14,1,3),MID(K14,5,LEN(K14)-4)),IF(MID(K14,5,1)=",",_xlfn.TEXTJOIN(".",FALSE,MID(K14,1,4),MID(K14,6,LEN(K14)-5)),K14)))) -> 243.8738808 | AO14: =IF(MID(L14,2,1)=",",_xlfn.TEXTJOIN(".",FALSE,MID(L14,1,1),MID(L14,3,LEN(L14)-2)),IF(MID(L14,3,1)=",",_xlfn.TEXTJOIN(".",FALSE,MID(L14,1,2),MID(L14,4,LEN(L14)-3)),IF(MID(L14,4,1)=",",_xlfn.TEXTJOIN(".",FALSE,MID(L14,1,3),MID(L14,5,LEN(L14)-4)),IF(MID(L14,5,1)=",",_xlfn.TEXTJOIN(".",FALSE,MID(L14,1,4),MID(L14,6,LEN(L14)-5)),L14)))) -> 16.19644182 | AP14: =IF(MID(M14,2,1)=",",_xlfn.TEXTJOIN(".",FALSE,MID(M14,1,1),MID(M14,3,LEN(M14)-2)),IF(MID(M14,3,1)=",",_xlfn.TEXTJOIN(".",FALSE,MID(M14,1,2),MID(M14,4,LEN(M14)-3)),IF(MID(M14,4,1)=",",_xlfn.TEXTJOIN(".",FALSE,MID(M14,1,3),MID(M14,5,LEN(M14)-4)),IF(MID(M14,5,1)=",",_xlfn.TEXTJOIN(".",FALSE,MID(M14,1,4),MID(M14,6,LEN(M14)-5)),M14)))) -> 250.2926038 | ... BJ14: =IF(MID(AG14,2,1)=",",_xlfn.TEXTJOIN(".",FALSE,MID(AG14,1,1),MID(AG14,3,LEN(AG14)-2)),IF(MID(AG14,3,1)=",",_xlfn.TEXTJOIN(".",FALSE,MID(AG14,1,2),MID(AG14,4,LEN(AG14)-3)),IF(MID(AG14,4,1)=",",_xlfn.TEXTJOIN(".",FALSE,MID(AG14,1,3),MID(AG14,5,LEN(AG14)-4)),IF(MID(AG14,5,1)=",",_xlfn.TEXTJOIN(".",FALSE,MID(AG14,1,4),MID(AG14,6,LEN(AG14)-5)),AG14)))) -> 8.476542913
